<?xml version="1.0" encoding="utf-8"?>
<!-- =================================================================================== -->
<!-- |    This document was autogenerated by xacro from xacro/robot.xacro              | -->
<!-- |    EDITING THIS FILE BY HAND IS NOT RECOMMENDED                                 | -->
<!-- =================================================================================== -->
<robot name="go1_description">
  <!-- Original value: 23.7 -->
  <material name="black">
    <color rgba="0.0 0.0 0.0 1.0"/>
  </material>
  <material name="blue">
    <color rgba="0.0 0.0 0.8 1.0"/>
  </material>
  <material name="green">
    <color rgba="0.0 0.8 0.0 1.0"/>
  </material>
  <material name="grey">
    <color rgba="0.2 0.2 0.2 1.0"/>
  </material>
  <material name="silver">
    <color rgba="0.913725490196 0.913725490196 0.847058823529 1.0"/>
  </material>
  <material name="orange">
    <color rgba="1.0 0.423529411765 0.0392156862745 1.0"/>
  </material>
  <material name="brown">
    <color rgba="0.870588235294 0.811764705882 0.764705882353 1.0"/>
  </material>
  <material name="red">
    <color rgba="0.8 0.0 0.0 1.0"/>
  </material>
  <material name="white">
    <color rgba="1.0 1.0 1.0 1.0"/>
  </material>
  <!-- ros_control plugin -->
  <gazebo>
    <plugin filename="libgazebo_ros_control.so" name="gazebo_ros_control">
      <robotSimType>gazebo_ros_control/DefaultRobotHWSim</robotSimType>
    </plugin>
    <plugin filename="libground_truth_estimator.so" name="ground_truth_estimator">
      <updateRateHZ>500.0</updateRateHZ>
    </plugin>
  </gazebo>
  <!-- Show the trajectory of trunk center. -->
  <!-- <gazebo>
        <plugin name="3dplot" filename="libLinkPlot3DPlugin.so">
            <frequency>10</frequency>
            <plot>
                <link>base</link>
                <pose>0 0 0 0 0 0</pose>
                <material>Gazebo/Yellow</material>
            </plot>
        </plugin>
    </gazebo> -->
  <!-- Show the trajectory of foot. You can add another trajectory about another foot. -->
  <!-- <gazebo>
        <plugin name="3dplot" filename="libLinkPlot3DPlugin.so">
            <frequency>100</frequency>
            <plot>
                <link>FL_foot</link>
                <pose>0 0 0 0 0 0</pose>
                <material>Gazebo/Green</material>
            </plot>
        </plugin>
    </gazebo> -->
  <gazebo>
    <plugin filename="libgazebo_ros_force.so" name="gazebo_ros_force">
      <bodyName>trunk</bodyName>
      <topicName>/apply_force/trunk</topicName>
    </plugin>
  </gazebo>
  <gazebo reference="imu_link">
    <gravity>true</gravity>
    <sensor name="imu_sensor" type="imu">
      <always_on>true</always_on>
      <update_rate>1000</update_rate>
      <visualize>true</visualize>
      <topic>__default_topic__</topic>
      <plugin filename="libgazebo_ros_imu_sensor.so" name="imu_plugin">
        <topicName>trunk_imu</topicName>
        <bodyName>imu_link</bodyName>
        <updateRateHZ>1000.0</updateRateHZ>
        <gaussianNoise>0.0</gaussianNoise>
        <xyzOffset>0 0 0</xyzOffset>
        <rpyOffset>0 0 0</rpyOffset>
        <frameName>imu_link</frameName>
      </plugin>
      <pose>0 0 0 0 0 0</pose>
    </sensor>
  </gazebo>
  <!-- Depth camera -->
  <!-- <gazebo>
        <plugin name="camera_plugin" filename="libgazebo_ros_openni_kinect.so">
            <baseline>0.025</baseline>
            <always_on>true</always_on>
            <updateRate>0.0</updateRate>
            <cameraName>unitree_camera_left</cameraName>
            <frameName>depthCamera_link_left</frameName>
            <imageTopicName>rgb/imageRaw_left</imageTopicName>
            <depthImageTopicName>depth/imageRaw_left</depthImageTopicName>
            <pointCloudTopicName>depth/points_left</pointCloudTopicName>
            <cameraInfoTopicName>rgb/cameraInfo_left</cameraInfoTopicName>              
            <depthImageCameraInfoTopicName>depth/cameraInfo_left</depthImageCameraInfoTopicName>            
            <pointCloudCutoff>0.1</pointCloudCutoff>                
            <pointCloudCutoffMax>1.5</pointCloudCutoffMax>                
            <distortionK1>0.0</distortionK1>
            <distortionK2>0.0</distortionK2>
            <distortionK3>0.0</distortionK3>
            <distortionT1>0.0</distortionT1>
            <distortionT2>0.0</distortionT2>
            <CxPrime>0.0</CxPrime>
            <Cx>0.0045</Cx>
            <Cy>0.0039</Cy>
            <focalLength>0.004</focalLength>
            <hackBaseline>0.0</hackBaseline>
        </plugin>
    </gazebo> -->
  <!-- <gazebo reference="depthCamera_link_left">
        <sensor name="unitree_camera_left" type="depth_camera">
            <update_rate>16</update_rate>
            <always_on>true</always_on>
            <visualize>true</visualize>
            <camera>
                <horizontal_fov>2.094</horizontal_fov>
                <image>
                    <width>928</width>
                    <height>800</height>
                    <format>R8G8B8</format>
                </image>
                <depth_camera></depth_camera>
                <clip>
                    <near>0.1</near>
                    <far>100</far>
                </clip>
            </camera>
            <plugin name="camera_plugin" filename="libgazebo_ros_openni_kinect.so">
                <baseline>0.025</baseline>
                <always_on>true</always_on>
                <updateRate>0.0</updateRate>
                <cameraName>unitree_camera_left</cameraName>
                <frameName>depthCamera_link_left</frameName>
                <imageTopicName>rgb/imageRaw_left</imageTopicName>
                <depthImageTopicName>depth/imageRaw_left</depthImageTopicName>
                <pointCloudTopicName>depth/points_left</pointCloudTopicName>
                <cameraInfoTopicName>rgb/cameraInfo_left</cameraInfoTopicName>              
                <depthImageCameraInfoTopicName>depth/cameraInfo_left</depthImageCameraInfoTopicName>            
                <pointCloudCutoff>0.1</pointCloudCutoff>                
                <pointCloudCutoffMax>1.5</pointCloudCutoffMax>                
                <distortionK1>0.0</distortionK1>
                <distortionK2>0.0</distortionK2>
                <distortionK3>0.0</distortionK3>
                <distortionT1>0.0</distortionT1>
                <distortionT2>0.0</distortionT2>
                <CxPrime>0.0</CxPrime>
                <Cx>0.0045</Cx>
                <Cy>0.0039</Cy>
                <focalLength>0.004</focalLength>
                <hackBaseline>0.0</hackBaseline>
            </plugin>
        </sensor>
    </gazebo> -->
  <gazebo reference="depthCamera_link_left">
    <sensor name="camera_link_camera" type="depth">
      <update_rate>20</update_rate>
      <camera>
        <horizontal_fov>1.047198</horizontal_fov>
        <image>
          <width>640</width>
          <height>480</height>
          <format>R8G8B8</format>
        </image>
        <clip>
          <near>0.05</near>
          <far>3</far>
        </clip>
      </camera>
      <plugin filename="libgazebo_ros_openni_kinect.so" name="camera_link_controller">
        <baseline>0.2</baseline>
        <alwaysOn>true</alwaysOn>
        <updateRate>1.0</updateRate>
        <cameraName>camera_link_ir</cameraName>
        <imageTopicName>/camera_link/color/image_raw</imageTopicName>
        <cameraInfoTopicName>/camera_link/color/camera_info</cameraInfoTopicName>
        <depthImageTopicName>/camera_link/depth/image_raw</depthImageTopicName>
        <depthImageInfoTopicName>/camera_link/depth/camera_info</depthImageInfoTopicName>
        <pointCloudTopicName>/camera_link/depth/points</pointCloudTopicName>
        <frameName>depthCamera_link_left</frameName>
        <pointCloudCutoff>0.5</pointCloudCutoff>
        <pointCloudCutoffMax>3.0</pointCloudCutoffMax>
        <distortionK1>0.00000001</distortionK1>
        <distortionK2>0.00000001</distortionK2>
        <distortionK3>0.00000001</distortionK3>
        <distortionT1>0.00000001</distortionT1>
        <distortionT2>0.00000001</distortionT2>
        <CxPrime>0</CxPrime>
        <Cx>0</Cx>
        <Cy>0</Cy>
        <focalLength>0</focalLength>
        <hackBaseline>0</hackBaseline>
      </plugin>
    </sensor>
  </gazebo>
  <!-- Foot contacts. -->
  <!-- <gazebo reference="FR_calf">
        <sensor name="FR_foot_contact" type="contact">
        <update_rate>100</update_rate>
        <plugin name="contactPlugin" filename="libunitreeFootContactPlugin.so"/>
        <contact>
            <collision>FR_calf_fixed_joint_lump__FR_foot_collision_1</collision>
        </contact>
        </sensor>
    </gazebo>
    <gazebo reference="FL_calf">
        <sensor name="FL_foot_contact" type="contact">
        <update_rate>100</update_rate>
        <plugin name="contactPlugin" filename="libunitreeFootContactPlugin.so"/>
        <contact>
            <collision>FL_calf_fixed_joint_lump__FL_foot_collision_1</collision>
        </contact>
        </sensor>
    </gazebo>
    <gazebo reference="RR_calf">
        <sensor name="RR_foot_contact" type="contact">
        <update_rate>100</update_rate>
        <plugin name="contactPlugin" filename="libunitreeFootContactPlugin.so"/>
        <contact>
            <collision>RR_calf_fixed_joint_lump__RR_foot_collision_1</collision>
        </contact>
        </sensor>
    </gazebo>
    <gazebo reference="RL_calf">
        <sensor name="RL_foot_contact" type="contact">
        <update_rate>100</update_rate>
        <plugin name="contactPlugin" filename="libunitreeFootContactPlugin.so"/>
        <contact>
            <collision>RL_calf_fixed_joint_lump__RL_foot_collision_1</collision>
        </contact>
        </sensor>
    </gazebo> -->
  <!-- Bumper plugin for contact sensors -->
  <!-- Make a macro for this later (low priority) -->
  <gazebo reference="toe0">
    <sensor name="toe0_contact" type="contact">
      <plugin filename="libgazebo_ros_bumper.so" name="toe0_plugin">
        <alwaysOn>true</alwaysOn>
        <updateRate>500</updateRate>
        <bumperTopicName>gazebo/toe0_contact_state</bumperTopicName>
        <frameName>world</frameName>
      </plugin>
      <contact>
        <collision>toe0_collision</collision>
      </contact>
      <update_rate>500</update_rate>
    </sensor>
  </gazebo>
  <gazebo reference="toe1">
    <sensor name="toe1_contact" type="contact">
      <plugin filename="libgazebo_ros_bumper.so" name="toe1_plugin">
        <alwaysOn>true</alwaysOn>
        <updateRate>500</updateRate>
        <bumperTopicName>gazebo/toe1_contact_state</bumperTopicName>
        <frameName>world</frameName>
      </plugin>
      <contact>
        <collision>toe1_collision</collision>
      </contact>
      <update_rate>500</update_rate>
    </sensor>
  </gazebo>
  <gazebo reference="toe2">
    <sensor name="toe2_contact" type="contact">
      <plugin filename="libgazebo_ros_bumper.so" name="toe2_plugin">
        <alwaysOn>true</alwaysOn>
        <updateRate>500</updateRate>
        <bumperTopicName>gazebo/toe2_contact_state</bumperTopicName>
        <frameName>world</frameName>
      </plugin>
      <contact>
        <collision>toe2_collision</collision>
      </contact>
      <update_rate>500</update_rate>
    </sensor>
  </gazebo>
  <gazebo reference="toe3">
    <sensor name="toe3_contact" type="contact">
      <plugin filename="libgazebo_ros_bumper.so" name="toe3_plugin">
        <alwaysOn>true</alwaysOn>
        <updateRate>500</updateRate>
        <bumperTopicName>gazebo/toe3_contact_state</bumperTopicName>
        <frameName>world</frameName>
      </plugin>
      <contact>
        <collision>toe3_collision</collision>
      </contact>
      <update_rate>500</update_rate>
    </sensor>
  </gazebo>
  <!-- Visualization of Foot contacts. -->
  <!-- <gazebo reference="FR_foot">
        <visual>
            <plugin name="drawForcePlugin" filename="libunitreeDrawForcePlugin.so">
                <topicName>FR_foot_contact</topicName>
            </plugin>
        </visual>
    </gazebo>
    <gazebo reference="FL_foot">
        <visual>
            <plugin name="drawForcePlugin" filename="libunitreeDrawForcePlugin.so">
                <topicName>FL_foot_contact</topicName>
            </plugin>
        </visual>
    </gazebo>
    <gazebo reference="RR_foot">
        <visual>
            <plugin name="drawForcePlugin" filename="libunitreeDrawForcePlugin.so">
                <topicName>RR_foot_contact</topicName>
            </plugin>
        </visual>
    </gazebo>
    <gazebo reference="RL_foot">
        <visual>
            <plugin name="drawForcePlugin" filename="libunitreeDrawForcePlugin.so">
                <topicName>RL_foot_contact</topicName>
            </plugin>
        </visual>
    </gazebo> -->
  <gazebo reference="body">
    <material>Gazebo/White</material>
    <turnGravityOff>false</turnGravityOff>
  </gazebo>
  <gazebo reference="trunk">
    <mu1>0.2</mu1>
    <mu2>0.2</mu2>
    <kp value="1000000.0"/>
    <kd value="1.0"/>
  </gazebo>
  <gazebo reference="stick_link">
    <mu1>0.2</mu1>
    <mu2>0.2</mu2>
    <material>Gazebo/White</material>
  </gazebo>
  <gazebo reference="imu_link">
    <mu1>0.2</mu1>
    <mu2>0.2</mu2>
    <material>Gazebo/Red</material>
  </gazebo>
  <!-- FL leg -->
  <gazebo reference="hip0">
    <mu1>0.2</mu1>
    <mu2>0.2</mu2>
    <material>Gazebo/DarkGrey</material>
  </gazebo>
  <gazebo reference="upper0">
    <mu1>0.2</mu1>
    <mu2>0.2</mu2>
    <self_collide>0</self_collide>
    <material>Gazebo/DarkGrey</material>
    <kp value="1000000.0"/>
    <kd value="1.0"/>
  </gazebo>
  <gazebo reference="lower0">
    <mu1>0.2</mu1>
    <mu2>0.2</mu2>
    <self_collide>0</self_collide>
  </gazebo>
  <gazebo reference="toe0">
    <mu1>0.6</mu1>
    <mu2>0.6</mu2>
    <self_collide>0</self_collide>
    <material>Gazebo/DarkGrey</material>
    <kp value="1000000.0"/>
    <kd value="1.0"/>
  </gazebo>
  <!-- RL leg -->
  <gazebo reference="hip1">
    <mu1>0.2</mu1>
    <mu2>0.2</mu2>
    <material>Gazebo/DarkGrey</material>
  </gazebo>
  <gazebo reference="upper1">
    <mu1>0.2</mu1>
    <mu2>0.2</mu2>
    <self_collide>0</self_collide>
    <material>Gazebo/DarkGrey</material>
    <kp value="1000000.0"/>
    <kd value="1.0"/>
  </gazebo>
  <gazebo reference="lower1">
    <mu1>0.2</mu1>
    <mu2>0.2</mu2>
    <self_collide>0</self_collide>
  </gazebo>
  <gazebo reference="toe1">
    <mu1>0.6</mu1>
    <mu2>0.6</mu2>
    <self_collide>0</self_collide>
    <material>Gazebo/DarkGrey</material>
    <kp value="1000000.0"/>
    <kd value="1.0"/>
  </gazebo>
  <!-- FR leg -->
  <gazebo reference="hip2">
    <mu1>0.2</mu1>
    <mu2>0.2</mu2>
    <material>Gazebo/DarkGrey</material>
  </gazebo>
  <gazebo reference="upper2">
    <mu1>0.2</mu1>
    <mu2>0.2</mu2>
    <self_collide>0</self_collide>
    <material>Gazebo/DarkGrey</material>
    <kp value="1000000.0"/>
    <kd value="1.0"/>
  </gazebo>
  <gazebo reference="lower2">
    <mu1>0.2</mu1>
    <mu2>0.2</mu2>
    <self_collide>0</self_collide>
  </gazebo>
  <gazebo reference="toe2">
    <mu1>0.6</mu1>
    <mu2>0.6</mu2>
    <self_collide>0</self_collide>
    <material>Gazebo/DarkGrey</material>
    <kp value="1000000.0"/>
    <kd value="1.0"/>
  </gazebo>
  <!-- RR leg -->
  <gazebo reference="hip3">
    <mu1>0.2</mu1>
    <mu2>0.2</mu2>
    <material>Gazebo/DarkGrey</material>
  </gazebo>
  <gazebo reference="upper3">
    <mu1>0.2</mu1>
    <mu2>0.2</mu2>
    <self_collide>0</self_collide>
    <material>Gazebo/DarkGrey</material>
    <kp value="1000000.0"/>
    <kd value="1.0"/>
  </gazebo>
  <gazebo reference="lower3">
    <mu1>0.2</mu1>
    <mu2>0.2</mu2>
    <self_collide>0</self_collide>
  </gazebo>
  <gazebo reference="toe3">
    <mu1>0.6</mu1>
    <mu2>0.6</mu2>
    <self_collide>0</self_collide>
    <material>Gazebo/DarkGrey</material>
    <kp value="1000000.0"/>
    <kd value="1.0"/>
  </gazebo>
  <!-- Preserve fixed joints -->
  <gazebo reference="jtoe0">
    <preserveFixedJoint>true</preserveFixedJoint>
  </gazebo>
  <gazebo reference="jtoe1">
    <preserveFixedJoint>true</preserveFixedJoint>
  </gazebo>
  <gazebo reference="jtoe2">
    <preserveFixedJoint>true</preserveFixedJoint>
  </gazebo>
  <gazebo reference="jtoe3">
    <preserveFixedJoint>true</preserveFixedJoint>
  </gazebo>
  <!-- <gazebo reference='floating_base'>
    <preserveFixedJoint>true</preserveFixedJoint>
    </gazebo> -->
  <gazebo reference="hip0_fixed">
    <preserveFixedJoint>true</preserveFixedJoint>
  </gazebo>
  <gazebo reference="hip1_fixed">
    <preserveFixedJoint>true</preserveFixedJoint>
  </gazebo>
  <gazebo reference="hip2_fixed">
    <preserveFixedJoint>true</preserveFixedJoint>
  </gazebo>
  <gazebo reference="hip3_fixed">
    <preserveFixedJoint>true</preserveFixedJoint>
  </gazebo>
  <!-- <xacro:include filename="$(find go1_gazebo)/launch/stairs.urdf.xacro"/> -->
  <!-- <xacro:stairs stairs="15" xpos="0" ypos="0" zpos="0" /> -->
  <link name="body">
    <visual>
      <origin rpy="0 0 0" xyz="0 0 0"/>
      <geometry>
        <box size="0.001 0.001 0.001"/>
      </geometry>
    </visual>
  </link>
  <joint name="floating_base" type="fixed">
    <origin rpy="0 0 0" xyz="0 0 0"/>
    <parent link="body"/>
    <child link="trunk"/>
  </joint>
  <link name="trunk">
    <visual name="body_visual">
      <origin rpy="0 0 0" xyz="0 0 0"/>
      <geometry>
        <mesh filename="package://go1_description/meshes/trunk.dae" scale="1 1 1"/>
      </geometry>
      <material name="silver"/>
    </visual>
    <collision name="body_collision">
      <origin rpy="0 0 0" xyz="0 0 0"/>
      <geometry>
        <box size="0.3762 0.0935 0.114"/>
      </geometry>
    </collision>
    <inertial>
      <origin rpy="0 0 0" xyz="0.0223 0.002 -0.0005"/>
      <mass value="5.204"/>
      <inertia ixx="0.0168352186" ixy="0.0004636141" ixz="0.0002367952" iyy="0.0656071082" iyz="3.6671e-05" izz="0.0742720659"/>
    </inertial>
  </link>
  <joint name="imu_joint" type="fixed">
    <parent link="trunk"/>
    <child link="imu_link"/>
    <origin rpy="0 0 0" xyz="-0.01592 -0.06659 -0.00617"/>
  </joint>
  <link name="imu_link">
    <inertial>
      <mass value="0.001"/>
      <origin rpy="0 0 0" xyz="0 0 0"/>
      <inertia ixx="0.0001" ixy="0" ixz="0" iyy="0.0001" iyz="0" izz="0.0001"/>
    </inertial>
    <visual>
      <origin rpy="0 0 0" xyz="0 0 0"/>
      <geometry>
        <box size="0.001 0.001 0.001"/>
      </geometry>
      <material name="red"/>
    </visual>
    <collision>
      <origin rpy="0 0 0" xyz="0 0 0"/>
      <geometry>
        <box size=".001 .001 .001"/>
      </geometry>
    </collision>
  </link>
  <!-- Hip Link -->
  <link name="hip0">
    <visual name="hip0_visual">
      <origin rpy="0 0 0" xyz="0 0 0"/>
      <geometry>
        <mesh filename="package://go1_description/meshes/hip.dae" scale="1 1 1"/>
      </geometry>
      <material name="orange"/>
    </visual>
    <collision name="hip0_collision">
      <origin rpy="1.57079632679 0 0" xyz="0 0 0"/>
      <geometry>
        <cylinder length="0.04" radius="0.046"/>
      </geometry>
    </collision>
    <inertial>
      <origin rpy="0 0 0" xyz="-0.00541 -0.00074 6e-06"/>
      <mass value="0.591"/>
      <inertia ixx="0.000374268192" ixy="3.6844422e-05" ixz="-9.86754e-07" iyy="0.000635923669" iyz="-1.172894e-06" izz="0.000457647394"/>
    </inertial>
  </link>
  <!-- Abduction Joint -->
  <joint name="8" type="revolute">
    <origin rpy="0 0 0" xyz="0.1881 0.04675 0"/>
    <parent link="trunk"/>
    <child link="hip0"/>
    <axis xyz="1 0 0"/>
    <dynamics damping="0.01" friction="0.2"/>
    <limit effort="23.7" lower="-1.0471975512" upper="1.0471975512" velocity="30.1"/>
  </joint>
  <!-- this link is only for collision -->
  <link name="thigh_shoulder0">
    <collision>
      <origin rpy="1.57079632679 0 0" xyz="0 0 0"/>
      <geometry>
        <cylinder length="0.032" radius="0.041"/>
      </geometry>
    </collision>
  </link>
  <!-- Hip Joint -->
  <joint name="hip0_fixed" type="fixed">
    <origin rpy="0 0 0" xyz="0 0.08 0"/>
    <parent link="hip0"/>
    <child link="thigh_shoulder0"/>
  </joint>
  <!-- Thigh link -->
  <link name="upper0">
    <visual name="upper0_visual">
      <origin rpy="0 0 0" xyz="0 0 0"/>
      <geometry>
        <mesh filename="package://go1_description/meshes/thigh.dae" scale="1 1 1"/>
      </geometry>
      <material name="orange"/>
    </visual>
    <collision name="upper0_collision">
      <origin rpy="0 1.57079632679 0" xyz="0 0 -0.1065"/>
      <geometry>
        <box size="0.213 0.0245 0.034"/>
      </geometry>
    </collision>
    <inertial>
      <origin rpy="0 0 0" xyz="-0.003468 -0.018947 -0.032736"/>
      <mass value="0.92"/>
      <inertia ixx="0.005851561134" ixy="1.783284e-06" ixz="0.000328291374" iyy="0.005596155105" iyz="2.1430713e-05" izz="0.00107157026"/>
    </inertial>
  </link>
  <!-- Upper leg joint -->
  <joint name="0" type="revolute">
    <!-- <origin rpy="0 ${PI/2} 0" xyz="0 ${thigh_offset*mirror} 0"/> -->
    <origin rpy="0 1.57079632679 0" xyz="0 0.08 0"/>
    <parent link="hip0"/>
    <child link="upper0"/>
    <axis xyz="0 -1 0"/>
    <dynamics damping="0.01" friction="0.2"/>
    <limit effort="23.7" lower="-6.28318530718" upper="6.28318530718" velocity="30.1"/>
  </joint>
  <!-- Lower leg link -->
  <link name="lower0">
    <visual name="lower0_visual">
      <origin rpy="0 0 0" xyz="0 0 0"/>
      <geometry>
        <mesh filename="package://go1_description/meshes/calf.dae" scale="1 1 1"/>
      </geometry>
      <material name="orange"/>
    </visual>
    <collision name="lower0_collision">
      <origin rpy="0 1.57079632679 0" xyz="0 0 -0.1065"/>
      <!-- origin rpy="0 ${PI/2.0} 0" xyz="0 0 ${-calf_length/2.0}"/ -->
      <geometry>
        <box size="0.213 0.016 0.016"/>
      </geometry>
    </collision>
    <inertial>
      <origin rpy="0 0 0" xyz="0.006286 0.001307 -0.122269"/>
      <mass value="0.131"/>
      <!-- ${calf_mass} -->
      <inertia ixx="0.002939186297" ixy="1.440899e-06" ixz="-0.00010535955" iyy="0.00295576935" iyz="-2.4397752e-05" izz="3.0273372e-05"/>
    </inertial>
  </link>
  <!-- Lower leg joint -->
  <joint name="1" type="revolute">
    <!-- <origin rpy="0 ${-PI} 0" xyz="0 0 ${-thigh_length}"/> -->
    <origin rpy="0 -3.14159265359 0" xyz="0 0 -0.213"/>
    <parent link="upper0"/>
    <child link="lower0"/>
    <axis xyz="0 1 0"/>
    <dynamics damping="0.01" friction="0.2"/>
    <limit effort="23.7" lower="-6.28318530718" upper="6.28318530718" velocity="30.1"/>
  </joint>
  <!-- Toe/Foot -->
  <link name="toe0">
    <visual name="toe0_visual">
      <origin rpy="0 0 0" xyz="0 0 0"/>
      <geometry>
        <sphere radius="0.01"/>
      </geometry>
      <material name="orange"/>
    </visual>
    <collision name="toe0_collision">
      <origin rpy="0 0 0" xyz="0 0 0"/>
      <geometry>
        <sphere radius="0.02"/>
      </geometry>
      <surface>
        <bounce>
          <restitution_coefficient>0</restitution_coefficient>
          <threshold>1e+06</threshold>
        </bounce>
        <friction>
          <ode>
            <mu>0.2</mu>
            <mu2>0.2</mu2>
          </ode>
          <bullet>
            <rolling_friction>0.3</rolling_friction>
            <friction2>50</friction2>
          </bullet>
        </friction>
        <contact>
          <ode>
            <kp>30000.0</kp>
            <kd>1000.0</kd>
          </ode>
          <bullet>
            <kp>30000.0</kp>
            <kd>1000.0</kd>
            <split_impulse>1</split_impulse>
            <split_impulse_penetration_threshold>-0.01</split_impulse_penetration_threshold>
          </bullet>
        </contact>
      </surface>
    </collision>
    <inertial>
      <mass value="0.06"/>
      <inertia ixx="9.6e-06" ixy="0.0" ixz="0.0" iyy="9.6e-06" iyz="0.0" izz="9.6e-06"/>
    </inertial>
  </link>
  <joint name="jtoe0" type="fixed">
    <origin rpy="0 0 0" xyz="0 0 -0.213"/>
    <parent link="lower0"/>
    <child link="toe0"/>
  </joint>
  <transmission name="transmission_8">
    <!-- hip transmission -->
    <type>transmission_interface/SimpleTransmission</type>
    <joint name="8">
      <hardwareInterface>hardware_interface/EffortJointInterface</hardwareInterface>
    </joint>
    <actuator name="motor_8">
      <hardwareInterface>EffortJointInterface</hardwareInterface>
      <mechanicalReduction>1</mechanicalReduction>
    </actuator>
  </transmission>
  <transmission name="transmission_0">
    <!-- Upper leg transmission -->
    <type>transmission_interface/SimpleTransmission</type>
    <joint name="0">
      <hardwareInterface>hardware_interface/EffortJointInterface</hardwareInterface>
    </joint>
    <actuator name="motor_0">
      <hardwareInterface>EffortJointInterface</hardwareInterface>
      <mechanicalReduction>1</mechanicalReduction>
    </actuator>
  </transmission>
  <transmission name="transmission_1">
    <!-- Lower Leg Transmission -->
    <type>transmission_interface/SimpleTransmission</type>
    <joint name="1">
      <hardwareInterface>hardware_interface/EffortJointInterface</hardwareInterface>
    </joint>
    <actuator name="motor_1">
      <hardwareInterface>EffortJointInterface</hardwareInterface>
      <mechanicalReduction>1</mechanicalReduction>
    </actuator>
  </transmission>
  <!-- Hip Link -->
  <link name="hip1">
    <visual name="hip1_visual">
      <origin rpy="0 3.14159265359 0" xyz="0 0 0"/>
      <geometry>
        <mesh filename="package://go1_description/meshes/hip.dae" scale="1 1 1"/>
      </geometry>
      <material name="orange"/>
    </visual>
    <collision name="hip1_collision">
      <origin rpy="1.57079632679 0 0" xyz="0 0 0"/>
      <geometry>
        <cylinder length="0.04" radius="0.046"/>
      </geometry>
    </collision>
    <inertial>
      <origin rpy="0 0 0" xyz="0.00541 -0.00074 6e-06"/>
      <mass value="0.591"/>
      <inertia ixx="0.000374268192" ixy="-3.6844422e-05" ixz="9.86754e-07" iyy="0.000635923669" iyz="-1.172894e-06" izz="0.000457647394"/>
    </inertial>
  </link>
  <!-- Abduction Joint -->
  <joint name="9" type="revolute">
    <origin rpy="0 0 0" xyz="-0.1881 0.04675 0"/>
    <parent link="trunk"/>
    <child link="hip1"/>
    <axis xyz="1 0 0"/>
    <dynamics damping="0.01" friction="0.2"/>
    <limit effort="23.7" lower="-1.0471975512" upper="1.0471975512" velocity="30.1"/>
  </joint>
  <!-- this link is only for collision -->
  <link name="thigh_shoulder1">
    <collision>
      <origin rpy="1.57079632679 0 0" xyz="0 0 0"/>
      <geometry>
        <cylinder length="0.032" radius="0.041"/>
      </geometry>
    </collision>
  </link>
  <!-- Hip Joint -->
  <joint name="hip1_fixed" type="fixed">
    <origin rpy="0 0 0" xyz="0 0.08 0"/>
    <parent link="hip1"/>
    <child link="thigh_shoulder1"/>
  </joint>
  <!-- Thigh link -->
  <link name="upper1">
    <visual name="upper1_visual">
      <origin rpy="0 0 0" xyz="0 0 0"/>
      <geometry>
        <mesh filename="package://go1_description/meshes/thigh.dae" scale="1 1 1"/>
      </geometry>
      <material name="orange"/>
    </visual>
    <collision name="upper1_collision">
      <origin rpy="0 1.57079632679 0" xyz="0 0 -0.1065"/>
      <geometry>
        <box size="0.213 0.0245 0.034"/>
      </geometry>
    </collision>
    <inertial>
      <origin rpy="0 0 0" xyz="-0.003468 -0.018947 -0.032736"/>
      <mass value="0.92"/>
      <inertia ixx="0.005851561134" ixy="1.783284e-06" ixz="0.000328291374" iyy="0.005596155105" iyz="2.1430713e-05" izz="0.00107157026"/>
    </inertial>
  </link>
  <!-- Upper leg joint -->
  <joint name="2" type="revolute">
    <!-- <origin rpy="0 ${PI/2} 0" xyz="0 ${thigh_offset*mirror} 0"/> -->
    <origin rpy="0 1.57079632679 0" xyz="0 0.08 0"/>
    <parent link="hip1"/>
    <child link="upper1"/>
    <axis xyz="0 -1 0"/>
    <dynamics damping="0.01" friction="0.2"/>
    <limit effort="23.7" lower="-6.28318530718" upper="6.28318530718" velocity="30.1"/>
  </joint>
  <!-- Lower leg link -->
  <link name="lower1">
    <visual name="lower1_visual">
      <origin rpy="0 0 0" xyz="0 0 0"/>
      <geometry>
        <mesh filename="package://go1_description/meshes/calf.dae" scale="1 1 1"/>
      </geometry>
      <material name="orange"/>
    </visual>
    <collision name="lower1_collision">
      <origin rpy="0 1.57079632679 0" xyz="0 0 -0.1065"/>
      <!-- origin rpy="0 ${PI/2.0} 0" xyz="0 0 ${-calf_length/2.0}"/ -->
      <geometry>
        <box size="0.213 0.016 0.016"/>
      </geometry>
    </collision>
    <inertial>
      <origin rpy="0 0 0" xyz="0.006286 0.001307 -0.122269"/>
      <mass value="0.131"/>
      <!-- ${calf_mass} -->
      <inertia ixx="0.002939186297" ixy="1.440899e-06" ixz="-0.00010535955" iyy="0.00295576935" iyz="-2.4397752e-05" izz="3.0273372e-05"/>
    </inertial>
  </link>
  <!-- Lower leg joint -->
  <joint name="3" type="revolute">
    <!-- <origin rpy="0 ${-PI} 0" xyz="0 0 ${-thigh_length}"/> -->
    <origin rpy="0 -3.14159265359 0" xyz="0 0 -0.213"/>
    <parent link="upper1"/>
    <child link="lower1"/>
    <axis xyz="0 1 0"/>
    <dynamics damping="0.01" friction="0.2"/>
    <limit effort="23.7" lower="-6.28318530718" upper="6.28318530718" velocity="30.1"/>
  </joint>
  <!-- Toe/Foot -->
  <link name="toe1">
    <visual name="toe1_visual">
      <origin rpy="0 0 0" xyz="0 0 0"/>
      <geometry>
        <sphere radius="0.01"/>
      </geometry>
      <material name="orange"/>
    </visual>
    <collision name="toe1_collision">
      <origin rpy="0 0 0" xyz="0 0 0"/>
      <geometry>
        <sphere radius="0.02"/>
      </geometry>
      <surface>
        <bounce>
          <restitution_coefficient>0</restitution_coefficient>
          <threshold>1e+06</threshold>
        </bounce>
        <friction>
          <ode>
            <mu>0.2</mu>
            <mu2>0.2</mu2>
          </ode>
          <bullet>
            <rolling_friction>0.3</rolling_friction>
            <friction2>50</friction2>
          </bullet>
        </friction>
        <contact>
          <ode>
            <kp>30000.0</kp>
            <kd>1000.0</kd>
          </ode>
          <bullet>
            <kp>30000.0</kp>
            <kd>1000.0</kd>
            <split_impulse>1</split_impulse>
            <split_impulse_penetration_threshold>-0.01</split_impulse_penetration_threshold>
          </bullet>
        </contact>
      </surface>
    </collision>
    <inertial>
      <mass value="0.06"/>
      <inertia ixx="9.6e-06" ixy="0.0" ixz="0.0" iyy="9.6e-06" iyz="0.0" izz="9.6e-06"/>
    </inertial>
  </link>
  <joint name="jtoe1" type="fixed">
    <origin rpy="0 0 0" xyz="0 0 -0.213"/>
    <parent link="lower1"/>
    <child link="toe1"/>
  </joint>
  <transmission name="transmission_9">
    <!-- hip transmission -->
    <type>transmission_interface/SimpleTransmission</type>
    <joint name="9">
      <hardwareInterface>hardware_interface/EffortJointInterface</hardwareInterface>
    </joint>
    <actuator name="motor_9">
      <hardwareInterface>EffortJointInterface</hardwareInterface>
      <mechanicalReduction>1</mechanicalReduction>
    </actuator>
  </transmission>
  <transmission name="transmission_2">
    <!-- Upper leg transmission -->
    <type>transmission_interface/SimpleTransmission</type>
    <joint name="2">
      <hardwareInterface>hardware_interface/EffortJointInterface</hardwareInterface>
    </joint>
    <actuator name="motor_2">
      <hardwareInterface>EffortJointInterface</hardwareInterface>
      <mechanicalReduction>1</mechanicalReduction>
    </actuator>
  </transmission>
  <transmission name="transmission_3">
    <!-- Lower Leg Transmission -->
    <type>transmission_interface/SimpleTransmission</type>
    <joint name="3">
      <hardwareInterface>hardware_interface/EffortJointInterface</hardwareInterface>
    </joint>
    <actuator name="motor_3">
      <hardwareInterface>EffortJointInterface</hardwareInterface>
      <mechanicalReduction>1</mechanicalReduction>
    </actuator>
  </transmission>
  <!-- Hip Link -->
  <link name="hip2">
    <visual name="hip2_visual">
      <origin rpy="3.14159265359 0 0" xyz="0 0 0"/>
      <geometry>
        <mesh filename="package://go1_description/meshes/hip.dae" scale="1 1 1"/>
      </geometry>
      <material name="orange"/>
    </visual>
    <collision name="hip2_collision">
      <origin rpy="1.57079632679 0 0" xyz="0 0 0"/>
      <geometry>
        <cylinder length="0.04" radius="0.046"/>
      </geometry>
    </collision>
    <inertial>
      <origin rpy="0 0 0" xyz="-0.00541 0.00074 6e-06"/>
      <mass value="0.591"/>
      <inertia ixx="0.000374268192" ixy="-3.6844422e-05" ixz="-9.86754e-07" iyy="0.000635923669" iyz="1.172894e-06" izz="0.000457647394"/>
    </inertial>
  </link>
  <!-- Abduction Joint -->
  <joint name="10" type="revolute">
    <origin rpy="0 0 0" xyz="0.1881 -0.04675 0"/>
    <parent link="trunk"/>
    <child link="hip2"/>
    <axis xyz="1 0 0"/>
    <dynamics damping="0.01" friction="0.2"/>
    <limit effort="23.7" lower="-1.0471975512" upper="1.0471975512" velocity="30.1"/>
  </joint>
  <!-- this link is only for collision -->
  <link name="thigh_shoulder2">
    <collision>
      <origin rpy="1.57079632679 0 0" xyz="0 0 0"/>
      <geometry>
        <cylinder length="0.032" radius="0.041"/>
      </geometry>
    </collision>
  </link>
  <!-- Hip Joint -->
  <joint name="hip2_fixed" type="fixed">
    <origin rpy="0 0 0" xyz="0 -0.08 0"/>
    <parent link="hip2"/>
    <child link="thigh_shoulder2"/>
  </joint>
  <!-- Thigh link -->
  <link name="upper2">
    <visual name="upper2_visual">
      <origin rpy="0 0 0" xyz="0 0 0"/>
      <geometry>
        <mesh filename="package://go1_description/meshes/thigh_mirror.dae" scale="1 1 1"/>
      </geometry>
      <material name="orange"/>
    </visual>
    <collision name="upper2_collision">
      <origin rpy="0 1.57079632679 0" xyz="0 0 -0.1065"/>
      <geometry>
        <box size="0.213 0.0245 0.034"/>
      </geometry>
    </collision>
    <inertial>
      <origin rpy="0 0 0" xyz="-0.003468 0.018947 -0.032736"/>
      <mass value="0.92"/>
      <inertia ixx="0.005851561134" ixy="-1.783284e-06" ixz="0.000328291374" iyy="0.005596155105" iyz="-2.1430713e-05" izz="0.00107157026"/>
    </inertial>
  </link>
  <!-- Upper leg joint -->
  <joint name="4" type="revolute">
    <!-- <origin rpy="0 ${PI/2} 0" xyz="0 ${thigh_offset*mirror} 0"/> -->
    <origin rpy="0 1.57079632679 0" xyz="0 -0.08 0"/>
    <parent link="hip2"/>
    <child link="upper2"/>
    <axis xyz="0 -1 0"/>
    <dynamics damping="0.01" friction="0.2"/>
    <limit effort="23.7" lower="-6.28318530718" upper="6.28318530718" velocity="30.1"/>
  </joint>
  <!-- Lower leg link -->
  <link name="lower2">
    <visual name="lower2_visual">
      <origin rpy="0 0 0" xyz="0 0 0"/>
      <geometry>
        <mesh filename="package://go1_description/meshes/calf.dae" scale="1 1 1"/>
      </geometry>
      <material name="orange"/>
    </visual>
    <collision name="lower2_collision">
      <origin rpy="0 1.57079632679 0" xyz="0 0 -0.1065"/>
      <!-- origin rpy="0 ${PI/2.0} 0" xyz="0 0 ${-calf_length/2.0}"/ -->
      <geometry>
        <box size="0.213 0.016 0.016"/>
      </geometry>
    </collision>
    <inertial>
      <origin rpy="0 0 0" xyz="0.006286 0.001307 -0.122269"/>
      <mass value="0.131"/>
      <!-- ${calf_mass} -->
      <inertia ixx="0.002939186297" ixy="1.440899e-06" ixz="-0.00010535955" iyy="0.00295576935" iyz="-2.4397752e-05" izz="3.0273372e-05"/>
    </inertial>
  </link>
  <!-- Lower leg joint -->
  <joint name="5" type="revolute">
    <!-- <origin rpy="0 ${-PI} 0" xyz="0 0 ${-thigh_length}"/> -->
    <origin rpy="0 -3.14159265359 0" xyz="0 0 -0.213"/>
    <parent link="upper2"/>
    <child link="lower2"/>
    <axis xyz="0 1 0"/>
    <dynamics damping="0.01" friction="0.2"/>
    <limit effort="23.7" lower="-6.28318530718" upper="6.28318530718" velocity="30.1"/>
  </joint>
  <!-- Toe/Foot -->
  <link name="toe2">
    <visual name="toe2_visual">
      <origin rpy="0 0 0" xyz="0 0 0"/>
      <geometry>
        <sphere radius="0.01"/>
      </geometry>
      <material name="orange"/>
    </visual>
    <collision name="toe2_collision">
      <origin rpy="0 0 0" xyz="0 0 0"/>
      <geometry>
        <sphere radius="0.02"/>
      </geometry>
      <surface>
        <bounce>
          <restitution_coefficient>0</restitution_coefficient>
          <threshold>1e+06</threshold>
        </bounce>
        <friction>
          <ode>
            <mu>0.2</mu>
            <mu2>0.2</mu2>
          </ode>
          <bullet>
            <rolling_friction>0.3</rolling_friction>
            <friction2>50</friction2>
          </bullet>
        </friction>
        <contact>
          <ode>
            <kp>30000.0</kp>
            <kd>1000.0</kd>
          </ode>
          <bullet>
            <kp>30000.0</kp>
            <kd>1000.0</kd>
            <split_impulse>1</split_impulse>
            <split_impulse_penetration_threshold>-0.01</split_impulse_penetration_threshold>
          </bullet>
        </contact>
      </surface>
    </collision>
    <inertial>
      <mass value="0.06"/>
      <inertia ixx="9.6e-06" ixy="0.0" ixz="0.0" iyy="9.6e-06" iyz="0.0" izz="9.6e-06"/>
    </inertial>
  </link>
  <joint name="jtoe2" type="fixed">
    <origin rpy="0 0 0" xyz="0 0 -0.213"/>
    <parent link="lower2"/>
    <child link="toe2"/>
  </joint>
  <transmission name="transmission_10">
    <!-- hip transmission -->
    <type>transmission_interface/SimpleTransmission</type>
    <joint name="10">
      <hardwareInterface>hardware_interface/EffortJointInterface</hardwareInterface>
    </joint>
    <actuator name="motor_10">
      <hardwareInterface>EffortJointInterface</hardwareInterface>
      <mechanicalReduction>1</mechanicalReduction>
    </actuator>
  </transmission>
  <transmission name="transmission_4">
    <!-- Upper leg transmission -->
    <type>transmission_interface/SimpleTransmission</type>
    <joint name="4">
      <hardwareInterface>hardware_interface/EffortJointInterface</hardwareInterface>
    </joint>
    <actuator name="motor_4">
      <hardwareInterface>EffortJointInterface</hardwareInterface>
      <mechanicalReduction>1</mechanicalReduction>
    </actuator>
  </transmission>
  <transmission name="transmission_5">
    <!-- Lower Leg Transmission -->
    <type>transmission_interface/SimpleTransmission</type>
    <joint name="5">
      <hardwareInterface>hardware_interface/EffortJointInterface</hardwareInterface>
    </joint>
    <actuator name="motor_5">
      <hardwareInterface>EffortJointInterface</hardwareInterface>
      <mechanicalReduction>1</mechanicalReduction>
    </actuator>
  </transmission>
  <!-- Hip Link -->
  <link name="hip3">
    <visual name="hip3_visual">
      <origin rpy="3.14159265359 3.14159265359 0" xyz="0 0 0"/>
      <geometry>
        <mesh filename="package://go1_description/meshes/hip.dae" scale="1 1 1"/>
      </geometry>
      <material name="orange"/>
    </visual>
    <collision name="hip3_collision">
      <origin rpy="1.57079632679 0 0" xyz="0 0 0"/>
      <geometry>
        <cylinder length="0.04" radius="0.046"/>
      </geometry>
    </collision>
    <inertial>
      <origin rpy="0 0 0" xyz="0.00541 0.00074 6e-06"/>
      <mass value="0.591"/>
      <inertia ixx="0.000374268192" ixy="3.6844422e-05" ixz="9.86754e-07" iyy="0.000635923669" iyz="1.172894e-06" izz="0.000457647394"/>
    </inertial>
  </link>
  <!-- Abduction Joint -->
  <joint name="11" type="revolute">
    <origin rpy="0 0 0" xyz="-0.1881 -0.04675 0"/>
    <parent link="trunk"/>
    <child link="hip3"/>
    <axis xyz="1 0 0"/>
    <dynamics damping="0.01" friction="0.2"/>
    <limit effort="23.7" lower="-1.0471975512" upper="1.0471975512" velocity="30.1"/>
  </joint>
  <!-- this link is only for collision -->
  <link name="thigh_shoulder3">
    <collision>
      <origin rpy="1.57079632679 0 0" xyz="0 0 0"/>
      <geometry>
        <cylinder length="0.032" radius="0.041"/>
      </geometry>
    </collision>
  </link>
  <!-- Hip Joint -->
  <joint name="hip3_fixed" type="fixed">
    <origin rpy="0 0 0" xyz="0 -0.08 0"/>
    <parent link="hip3"/>
    <child link="thigh_shoulder3"/>
  </joint>
  <!-- Thigh link -->
  <link name="upper3">
    <visual name="upper3_visual">
      <origin rpy="0 0 0" xyz="0 0 0"/>
      <geometry>
        <mesh filename="package://go1_description/meshes/thigh_mirror.dae" scale="1 1 1"/>
      </geometry>
      <material name="orange"/>
    </visual>
    <collision name="upper3_collision">
      <origin rpy="0 1.57079632679 0" xyz="0 0 -0.1065"/>
      <geometry>
        <box size="0.213 0.0245 0.034"/>
      </geometry>
    </collision>
    <inertial>
      <origin rpy="0 0 0" xyz="-0.003468 0.018947 -0.032736"/>
      <mass value="0.92"/>
      <inertia ixx="0.005851561134" ixy="-1.783284e-06" ixz="0.000328291374" iyy="0.005596155105" iyz="-2.1430713e-05" izz="0.00107157026"/>
    </inertial>
  </link>
  <!-- Upper leg joint -->
  <joint name="6" type="revolute">
    <!-- <origin rpy="0 ${PI/2} 0" xyz="0 ${thigh_offset*mirror} 0"/> -->
    <origin rpy="0 1.57079632679 0" xyz="0 -0.08 0"/>
    <parent link="hip3"/>
    <child link="upper3"/>
    <axis xyz="0 -1 0"/>
    <dynamics damping="0.01" friction="0.2"/>
    <limit effort="23.7" lower="-6.28318530718" upper="6.28318530718" velocity="30.1"/>
  </joint>
  <!-- Lower leg link -->
  <link name="lower3">
    <visual name="lower3_visual">
      <origin rpy="0 0 0" xyz="0 0 0"/>
      <geometry>
        <mesh filename="package://go1_description/meshes/calf.dae" scale="1 1 1"/>
      </geometry>
      <material name="orange"/>
    </visual>
    <collision name="lower3_collision">
      <origin rpy="0 1.57079632679 0" xyz="0 0 -0.1065"/>
      <!-- origin rpy="0 ${PI/2.0} 0" xyz="0 0 ${-calf_length/2.0}"/ -->
      <geometry>
        <box size="0.213 0.016 0.016"/>
      </geometry>
    </collision>
    <inertial>
      <origin rpy="0 0 0" xyz="0.006286 0.001307 -0.122269"/>
      <mass value="0.131"/>
      <!-- ${calf_mass} -->
      <inertia ixx="0.002939186297" ixy="1.440899e-06" ixz="-0.00010535955" iyy="0.00295576935" iyz="-2.4397752e-05" izz="3.0273372e-05"/>
    </inertial>
  </link>
  <!-- Lower leg joint -->
  <joint name="7" type="revolute">
    <!-- <origin rpy="0 ${-PI} 0" xyz="0 0 ${-thigh_length}"/> -->
    <origin rpy="0 -3.14159265359 0" xyz="0 0 -0.213"/>
    <parent link="upper3"/>
    <child link="lower3"/>
    <axis xyz="0 1 0"/>
    <dynamics damping="0.01" friction="0.2"/>
    <limit effort="23.7" lower="-6.28318530718" upper="6.28318530718" velocity="30.1"/>
  </joint>
  <!-- Toe/Foot -->
  <link name="toe3">
    <visual name="toe3_visual">
      <origin rpy="0 0 0" xyz="0 0 0"/>
      <geometry>
        <sphere radius="0.01"/>
      </geometry>
      <material name="orange"/>
    </visual>
    <collision name="toe3_collision">
      <origin rpy="0 0 0" xyz="0 0 0"/>
      <geometry>
        <sphere radius="0.02"/>
      </geometry>
      <surface>
        <bounce>
          <restitution_coefficient>0</restitution_coefficient>
          <threshold>1e+06</threshold>
        </bounce>
        <friction>
          <ode>
            <mu>0.2</mu>
            <mu2>0.2</mu2>
          </ode>
          <bullet>
            <rolling_friction>0.3</rolling_friction>
            <friction2>50</friction2>
          </bullet>
        </friction>
        <contact>
          <ode>
            <kp>30000.0</kp>
            <kd>1000.0</kd>
          </ode>
          <bullet>
            <kp>30000.0</kp>
            <kd>1000.0</kd>
            <split_impulse>1</split_impulse>
            <split_impulse_penetration_threshold>-0.01</split_impulse_penetration_threshold>
          </bullet>
        </contact>
      </surface>
    </collision>
    <inertial>
      <mass value="0.06"/>
      <inertia ixx="9.6e-06" ixy="0.0" ixz="0.0" iyy="9.6e-06" iyz="0.0" izz="9.6e-06"/>
    </inertial>
  </link>
  <joint name="jtoe3" type="fixed">
    <origin rpy="0 0 0" xyz="0 0 -0.213"/>
    <parent link="lower3"/>
    <child link="toe3"/>
  </joint>
  <transmission name="transmission_11">
    <!-- hip transmission -->
    <type>transmission_interface/SimpleTransmission</type>
    <joint name="11">
      <hardwareInterface>hardware_interface/EffortJointInterface</hardwareInterface>
    </joint>
    <actuator name="motor_11">
      <hardwareInterface>EffortJointInterface</hardwareInterface>
      <mechanicalReduction>1</mechanicalReduction>
    </actuator>
  </transmission>
  <transmission name="transmission_6">
    <!-- Upper leg transmission -->
    <type>transmission_interface/SimpleTransmission</type>
    <joint name="6">
      <hardwareInterface>hardware_interface/EffortJointInterface</hardwareInterface>
    </joint>
    <actuator name="motor_6">
      <hardwareInterface>EffortJointInterface</hardwareInterface>
      <mechanicalReduction>1</mechanicalReduction>
    </actuator>
  </transmission>
  <transmission name="transmission_7">
    <!-- Lower Leg Transmission -->
    <type>transmission_interface/SimpleTransmission</type>
    <joint name="7">
      <hardwareInterface>hardware_interface/EffortJointInterface</hardwareInterface>
    </joint>
    <actuator name="motor_7">
      <hardwareInterface>EffortJointInterface</hardwareInterface>
      <mechanicalReduction>1</mechanicalReduction>
    </actuator>
  </transmission>
  <joint name="camera_joint_face" type="fixed">
    <origin rpy="3.14159265359 0 0" xyz="0.2785 0.0125 0.0167"/>
    <parent link="trunk"/>
    <child link="camera_face"/>
  </joint>
  <link name="camera_face">
    <collision>
      <origin rpy="0 0 0" xyz="0 0 0"/>
      <geometry>
        <box size=".001 .001 .001"/>
      </geometry>
    </collision>
    <visual>
      <origin rpy="0 0 0" xyz="0 0 0"/>
      <geometry>
        <mesh filename="package://go1_description/meshes/depthCamera.dae" scale="1 1 1"/>
      </geometry>
    </visual>
    <inertial>
      <mass value="1e-5"/>
      <origin rpy="0 0 0" xyz="0 0 0"/>
      <inertia ixx="1e-6" ixy="0" ixz="0" iyy="1e-6" iyz="0" izz="1e-6"/>
    </inertial>
  </link>
  <joint name="camera_optical_joint_face" type="fixed">
    <origin rpy="-1.57079632679 0 -1.57079632679" xyz="0 0 0"/>
    <parent link="camera_face"/>
    <child link="camera_optical_face"/>
  </joint>
  <link name="camera_optical_face">
        </link>
  <gazebo reference="camera_face">
    <!-- <material>Gazebo/Black</material> -->
    <sensor name="camera_face_camera" type="depth">
      <update_rate>16</update_rate>
      <camera>
        <horizontal_fov>2.094</horizontal_fov>
        <image>
          <width>928</width>
          <height>800</height>
          <format>R8G8B8</format>
        </image>
        <clip>
          <near>0.1</near>
          <far>5</far>
        </clip>
      </camera>
      <plugin filename="libgazebo_ros_openni_kinect.so" name="camera_face_controller">
        <baseline>0.025</baseline>
        <alwaysOn>true</alwaysOn>
        <updateRate>0.0</updateRate>
        <cameraName>camera_face_ir</cameraName>
        <imageTopicName>/camera_face/color/image_raw</imageTopicName>
        <cameraInfoTopicName>/camera_face/color/camera_info</cameraInfoTopicName>
        <depthImageTopicName>/camera_face/depth/image_raw</depthImageTopicName>
        <depthImageInfoTopicName>/camera_face/depth/camera_info</depthImageInfoTopicName>
        <!-- <pointCloudTopicName>/camera_${name}/depth/points</pointCloudTopicName> -->
        <pointCloudTopicName>/cam1/point_cloud_face</pointCloudTopicName>
        <frameName>camera_optical_face</frameName>
        <pointCloudCutoff>0.1</pointCloudCutoff>
        <pointCloudCutoffMax>1.5</pointCloudCutoffMax>
        <distortionK1>0.0</distortionK1>
        <distortionK2>0.0</distortionK2>
        <distortionK3>0.0</distortionK3>
        <distortionT1>0.0</distortionT1>
        <distortionT2>0.0</distortionT2>
        <CxPrime>0</CxPrime>
        <Cx>0.0045</Cx>
        <Cy>0.0039</Cy>
        <focalLength>0</focalLength>
        <hackBaseline>0</hackBaseline>
      </plugin>
    </sensor>
  </gazebo>
  <joint name="camera_joint_chin" type="fixed">
    <origin rpy="3.14159265359 1.57079632679 0" xyz="0.2522 0.0125 -0.0436"/>
    <parent link="trunk"/>
    <child link="camera_chin"/>
  </joint>
  <link name="camera_chin">
    <collision>
      <origin rpy="0 0 0" xyz="0 0 0"/>
      <geometry>
        <box size=".001 .001 .001"/>
      </geometry>
    </collision>
    <visual>
      <origin rpy="0 0 0" xyz="0 0 0"/>
      <geometry>
        <mesh filename="package://go1_description/meshes/depthCamera.dae" scale="1 1 1"/>
      </geometry>
    </visual>
    <inertial>
      <mass value="1e-5"/>
      <origin rpy="0 0 0" xyz="0 0 0"/>
      <inertia ixx="1e-6" ixy="0" ixz="0" iyy="1e-6" iyz="0" izz="1e-6"/>
    </inertial>
  </link>
  <joint name="camera_optical_joint_chin" type="fixed">
    <origin rpy="-1.57079632679 0 -1.57079632679" xyz="0 0 0"/>
    <parent link="camera_chin"/>
    <child link="camera_optical_chin"/>
  </joint>
  <link name="camera_optical_chin">
        </link>
  <gazebo reference="camera_chin">
    <!-- <material>Gazebo/Black</material> -->
    <sensor name="camera_chin_camera" type="depth">
      <update_rate>16</update_rate>
      <camera>
        <horizontal_fov>2.094</horizontal_fov>
        <image>
          <width>928</width>
          <height>800</height>
          <format>R8G8B8</format>
        </image>
        <clip>
          <near>0.1</near>
          <far>5</far>
        </clip>
      </camera>
      <plugin filename="libgazebo_ros_openni_kinect.so" name="camera_chin_controller">
        <baseline>0.025</baseline>
        <alwaysOn>true</alwaysOn>
        <updateRate>0.0</updateRate>
        <cameraName>camera_chin_ir</cameraName>
        <imageTopicName>/camera_chin/color/image_raw</imageTopicName>
        <cameraInfoTopicName>/camera_chin/color/camera_info</cameraInfoTopicName>
        <depthImageTopicName>/camera_chin/depth/image_raw</depthImageTopicName>
        <depthImageInfoTopicName>/camera_chin/depth/camera_info</depthImageInfoTopicName>
        <!-- <pointCloudTopicName>/camera_${name}/depth/points</pointCloudTopicName> -->
        <pointCloudTopicName>/cam2/point_cloud_chin</pointCloudTopicName>
        <frameName>camera_optical_chin</frameName>
        <pointCloudCutoff>0.1</pointCloudCutoff>
        <pointCloudCutoffMax>1.5</pointCloudCutoffMax>
        <distortionK1>0.0</distortionK1>
        <distortionK2>0.0</distortionK2>
        <distortionK3>0.0</distortionK3>
        <distortionT1>0.0</distortionT1>
        <distortionT2>0.0</distortionT2>
        <CxPrime>0</CxPrime>
        <Cx>0.0045</Cx>
        <Cy>0.0039</Cy>
        <focalLength>0</focalLength>
        <hackBaseline>0</hackBaseline>
      </plugin>
    </sensor>
  </gazebo>
  <joint name="camera_joint_left" type="fixed">
    <origin rpy="3.14159265359 0.2618 1.57079632679" xyz="-0.066 0.082 -0.0176"/>
    <parent link="trunk"/>
    <child link="camera_left"/>
  </joint>
  <link name="camera_left">
    <collision>
      <origin rpy="0 0 0" xyz="0 0 0"/>
      <geometry>
        <box size=".001 .001 .001"/>
      </geometry>
    </collision>
    <visual>
      <origin rpy="0 0 0" xyz="0 0 0"/>
      <geometry>
        <mesh filename="package://go1_description/meshes/depthCamera.dae" scale="1 1 1"/>
      </geometry>
    </visual>
    <inertial>
      <mass value="1e-5"/>
      <origin rpy="0 0 0" xyz="0 0 0"/>
      <inertia ixx="1e-6" ixy="0" ixz="0" iyy="1e-6" iyz="0" izz="1e-6"/>
    </inertial>
  </link>
  <joint name="camera_optical_joint_left" type="fixed">
    <origin rpy="-1.57079632679 0 -1.57079632679" xyz="0 0 0"/>
    <parent link="camera_left"/>
    <child link="camera_optical_left"/>
  </joint>
  <link name="camera_optical_left">
        </link>
  <gazebo reference="camera_left">
    <!-- <material>Gazebo/Black</material> -->
    <sensor name="camera_left_camera" type="depth">
      <update_rate>16</update_rate>
      <camera>
        <horizontal_fov>2.094</horizontal_fov>
        <image>
          <width>928</width>
          <height>800</height>
          <format>R8G8B8</format>
        </image>
        <clip>
          <near>0.1</near>
          <far>5</far>
        </clip>
      </camera>
      <plugin filename="libgazebo_ros_openni_kinect.so" name="camera_left_controller">
        <baseline>0.025</baseline>
        <alwaysOn>true</alwaysOn>
        <updateRate>0.0</updateRate>
        <cameraName>camera_left_ir</cameraName>
        <imageTopicName>/camera_left/color/image_raw</imageTopicName>
        <cameraInfoTopicName>/camera_left/color/camera_info</cameraInfoTopicName>
        <depthImageTopicName>/camera_left/depth/image_raw</depthImageTopicName>
        <depthImageInfoTopicName>/camera_left/depth/camera_info</depthImageInfoTopicName>
        <!-- <pointCloudTopicName>/camera_${name}/depth/points</pointCloudTopicName> -->
        <pointCloudTopicName>/cam3/point_cloud_left</pointCloudTopicName>
        <frameName>camera_optical_left</frameName>
        <pointCloudCutoff>0.1</pointCloudCutoff>
        <pointCloudCutoffMax>1.5</pointCloudCutoffMax>
        <distortionK1>0.0</distortionK1>
        <distortionK2>0.0</distortionK2>
        <distortionK3>0.0</distortionK3>
        <distortionT1>0.0</distortionT1>
        <distortionT2>0.0</distortionT2>
        <CxPrime>0</CxPrime>
        <Cx>0.0045</Cx>
        <Cy>0.0039</Cy>
        <focalLength>0</focalLength>
        <hackBaseline>0</hackBaseline>
      </plugin>
    </sensor>
  </gazebo>
  <joint name="camera_joint_right" type="fixed">
    <origin rpy="3.14159265359 0.2618 -1.57079632679" xyz="-0.041 -0.082 -0.0176"/>
    <parent link="trunk"/>
    <child link="camera_right"/>
  </joint>
  <link name="camera_right">
    <collision>
      <origin rpy="0 0 0" xyz="0 0 0"/>
      <geometry>
        <box size=".001 .001 .001"/>
      </geometry>
    </collision>
    <visual>
      <origin rpy="0 0 0" xyz="0 0 0"/>
      <geometry>
        <mesh filename="package://go1_description/meshes/depthCamera.dae" scale="1 1 1"/>
      </geometry>
    </visual>
    <inertial>
      <mass value="1e-5"/>
      <origin rpy="0 0 0" xyz="0 0 0"/>
      <inertia ixx="1e-6" ixy="0" ixz="0" iyy="1e-6" iyz="0" izz="1e-6"/>
    </inertial>
  </link>
  <joint name="camera_optical_joint_right" type="fixed">
    <origin rpy="-1.57079632679 0 -1.57079632679" xyz="0 0 0"/>
    <parent link="camera_right"/>
    <child link="camera_optical_right"/>
  </joint>
  <link name="camera_optical_right">
        </link>
  <gazebo reference="camera_right">
    <!-- <material>Gazebo/Black</material> -->
    <sensor name="camera_right_camera" type="depth">
      <update_rate>16</update_rate>
      <camera>
        <horizontal_fov>2.094</horizontal_fov>
        <image>
          <width>928</width>
          <height>800</height>
          <format>R8G8B8</format>
        </image>
        <clip>
          <near>0.1</near>
          <far>5</far>
        </clip>
      </camera>
      <plugin filename="libgazebo_ros_openni_kinect.so" name="camera_right_controller">
        <baseline>0.025</baseline>
        <alwaysOn>true</alwaysOn>
        <updateRate>0.0</updateRate>
        <cameraName>camera_right_ir</cameraName>
        <imageTopicName>/camera_right/color/image_raw</imageTopicName>
        <cameraInfoTopicName>/camera_right/color/camera_info</cameraInfoTopicName>
        <depthImageTopicName>/camera_right/depth/image_raw</depthImageTopicName>
        <depthImageInfoTopicName>/camera_right/depth/camera_info</depthImageInfoTopicName>
        <!-- <pointCloudTopicName>/camera_${name}/depth/points</pointCloudTopicName> -->
        <pointCloudTopicName>/cam4/point_cloud_right</pointCloudTopicName>
        <frameName>camera_optical_right</frameName>
        <pointCloudCutoff>0.1</pointCloudCutoff>
        <pointCloudCutoffMax>1.5</pointCloudCutoffMax>
        <distortionK1>0.0</distortionK1>
        <distortionK2>0.0</distortionK2>
        <distortionK3>0.0</distortionK3>
        <distortionT1>0.0</distortionT1>
        <distortionT2>0.0</distortionT2>
        <CxPrime>0</CxPrime>
        <Cx>0.0045</Cx>
        <Cy>0.0039</Cy>
        <focalLength>0</focalLength>
        <hackBaseline>0</hackBaseline>
      </plugin>
    </sensor>
  </gazebo>
  <joint name="camera_joint_rearDown" type="fixed">
    <origin rpy="3.14159265359 1.57079632679 0" xyz="-0.0825 0.0125 -0.04365"/>
    <parent link="trunk"/>
    <child link="camera_rearDown"/>
  </joint>
  <link name="camera_rearDown">
    <collision>
      <origin rpy="0 0 0" xyz="0 0 0"/>
      <geometry>
        <box size=".001 .001 .001"/>
      </geometry>
    </collision>
    <visual>
      <origin rpy="0 0 0" xyz="0 0 0"/>
      <geometry>
        <mesh filename="package://go1_description/meshes/depthCamera.dae" scale="1 1 1"/>
      </geometry>
    </visual>
    <inertial>
      <mass value="1e-5"/>
      <origin rpy="0 0 0" xyz="0 0 0"/>
      <inertia ixx="1e-6" ixy="0" ixz="0" iyy="1e-6" iyz="0" izz="1e-6"/>
    </inertial>
  </link>
  <joint name="camera_optical_joint_rearDown" type="fixed">
    <origin rpy="-1.57079632679 0 -1.57079632679" xyz="0 0 0"/>
    <parent link="camera_rearDown"/>
    <child link="camera_optical_rearDown"/>
  </joint>
  <link name="camera_optical_rearDown">
        </link>
  <gazebo reference="camera_rearDown">
    <!-- <material>Gazebo/Black</material> -->
    <sensor name="camera_rearDown_camera" type="depth">
      <update_rate>16</update_rate>
      <camera>
        <horizontal_fov>2.094</horizontal_fov>
        <image>
          <width>928</width>
          <height>800</height>
          <format>R8G8B8</format>
        </image>
        <clip>
          <near>0.1</near>
          <far>5</far>
        </clip>
      </camera>
      <plugin filename="libgazebo_ros_openni_kinect.so" name="camera_rearDown_controller">
        <baseline>0.025</baseline>
        <alwaysOn>true</alwaysOn>
        <updateRate>0.0</updateRate>
        <cameraName>camera_rearDown_ir</cameraName>
        <imageTopicName>/camera_rearDown/color/image_raw</imageTopicName>
        <cameraInfoTopicName>/camera_rearDown/color/camera_info</cameraInfoTopicName>
        <depthImageTopicName>/camera_rearDown/depth/image_raw</depthImageTopicName>
        <depthImageInfoTopicName>/camera_rearDown/depth/camera_info</depthImageInfoTopicName>
        <!-- <pointCloudTopicName>/camera_${name}/depth/points</pointCloudTopicName> -->
        <pointCloudTopicName>/cam5/point_cloud_rearDown</pointCloudTopicName>
        <frameName>camera_optical_rearDown</frameName>
        <pointCloudCutoff>0.1</pointCloudCutoff>
        <pointCloudCutoffMax>1.5</pointCloudCutoffMax>
        <distortionK1>0.0</distortionK1>
        <distortionK2>0.0</distortionK2>
        <distortionK3>0.0</distortionK3>
        <distortionT1>0.0</distortionT1>
        <distortionT2>0.0</distortionT2>
        <CxPrime>0</CxPrime>
        <Cx>0.0045</Cx>
        <Cy>0.0039</Cy>
        <focalLength>0</focalLength>
        <hackBaseline>0</hackBaseline>
      </plugin>
    </sensor>
  </gazebo>
  <joint name="camera_laserscan_joint_left" type="fixed">
    <origin rpy="0 0.2618 0" xyz="0 0 0"/>
    <parent link="camera_left"/>
    <child link="camera_laserscan_link_left"/>
  </joint>
  <link name="camera_laserscan_link_left">
    </link>
  <joint name="camera_laserscan_joint_right" type="fixed">
    <origin rpy="0 0.2618 0" xyz="0 0 0"/>
    <parent link="camera_right"/>
    <child link="camera_laserscan_link_right"/>
  </joint>
  <link name="camera_laserscan_link_right">
    </link>
  <joint name="ultraSound_joint_left" type="fixed">
    <origin rpy="0 0.2618 1.57079632679" xyz="-0.0535  0.0826 0.00868"/>
    <parent link="trunk"/>
    <child link="ultraSound_left"/>
  </joint>
  <link name="ultraSound_left">
    <collision>
      <origin rpy="0 0 0" xyz="0 0 0"/>
      <geometry>
        <box size=".001 .001 .001"/>
      </geometry>
    </collision>
    <visual>
      <origin rpy="0 0 0" xyz="0 0 0"/>
      <geometry>
        <mesh filename="package://go1_description/meshes/ultraSound.dae" scale="1 1 1"/>
      </geometry>
      <material name="black"/>
    </visual>
    <inertial>
      <mass value="1e-5"/>
      <origin rpy="0 0 0" xyz="0 0 0"/>
      <inertia ixx="1e-6" ixy="0" ixz="0" iyy="1e-6" iyz="0" izz="1e-6"/>
    </inertial>
  </link>
  <joint name="ultraSound_joint_right" type="fixed">
    <origin rpy="0 0.2618 -1.57079632679" xyz="-0.0535 -0.0826 0.00868"/>
    <parent link="trunk"/>
    <child link="ultraSound_right"/>
  </joint>
  <link name="ultraSound_right">
    <collision>
      <origin rpy="0 0 0" xyz="0 0 0"/>
      <geometry>
        <box size=".001 .001 .001"/>
      </geometry>
    </collision>
    <visual>
      <origin rpy="0 0 0" xyz="0 0 0"/>
      <geometry>
        <mesh filename="package://go1_description/meshes/ultraSound.dae" scale="1 1 1"/>
      </geometry>
      <material name="black"/>
    </visual>
    <inertial>
      <mass value="1e-5"/>
      <origin rpy="0 0 0" xyz="0 0 0"/>
      <inertia ixx="1e-6" ixy="0" ixz="0" iyy="1e-6" iyz="0" izz="1e-6"/>
    </inertial>
  </link>
  <joint name="ultraSound_joint_face" type="fixed">
    <origin rpy="0 0 0" xyz="0.2747 0.0 -0.0088"/>
    <parent link="trunk"/>
    <child link="ultraSound_face"/>
  </joint>
  <link name="ultraSound_face">
    <collision>
      <origin rpy="0 0 0" xyz="0 0 0"/>
      <geometry>
        <box size=".001 .001 .001"/>
      </geometry>
    </collision>
    <visual>
      <origin rpy="0 0 0" xyz="0 0 0"/>
      <geometry>
        <mesh filename="package://go1_description/meshes/ultraSound.dae" scale="1 1 1"/>
      </geometry>
      <material name="black"/>
    </visual>
    <inertial>
      <mass value="1e-5"/>
      <origin rpy="0 0 0" xyz="0 0 0"/>
      <inertia ixx="1e-6" ixy="0" ixz="0" iyy="1e-6" iyz="0" izz="1e-6"/>
    </inertial>
  </link>
</robot>
