<sdf version='1.6'>
  <model name='go1_description'>
    <link name='body'>
      <pose frame=''>0 0 0 0 -0 0</pose>
      <inertial>
        <pose frame=''>0.022293 0.001987 -0.000501 0 -0 0</pose>
        <mass>5.20508</mass>
        <inertia>
          <ixx>0.0169483</ixx>
          <ixy>0.000460972</ixy>
          <ixz>0.000236597</ixz>
          <iyy>0.0657188</iyy>
          <iyz>3.62889e-05</iyz>
          <izz>0.0743887</izz>
        </inertia>
      </inertial>
      <collision name='body_collision_collision'>
        <pose frame=''>0 0 0 0 -0 0</pose>
        <geometry>
          <box>
            <size>0.3762 0.0935 0.114</size>
          </box>
        </geometry>
        <surface>
          <contact>
            <ode/>
          </contact>
          <friction>
            <ode/>
          </friction>
        </surface>
      </collision>
      <collision name='body_fixed_joint_lump__camera_chin_collision_1'>
        <pose frame=''>0.2522 0.0125 -0.0436 3.14159 1.57079 3e-06</pose>
        <geometry>
          <box>
            <size>0.001 0.001 0.001</size>
          </box>
        </geometry>
        <surface>
          <contact>
            <ode/>
          </contact>
          <friction>
            <ode/>
          </friction>
        </surface>
      </collision>
      <collision name='body_fixed_joint_lump__camera_face_collision_2'>
        <pose frame=''>0.2785 0.0125 0.0167 -3.14159 -0 0</pose>
        <geometry>
          <box>
            <size>0.001 0.001 0.001</size>
          </box>
        </geometry>
        <surface>
          <contact>
            <ode/>
          </contact>
          <friction>
            <ode/>
          </friction>
        </surface>
      </collision>
      <collision name='body_fixed_joint_lump__camera_left_collision_3'>
        <pose frame=''>-0.066 0.082 -0.0176 -3.14159 0.2618 1.5708</pose>
        <geometry>
          <box>
            <size>0.001 0.001 0.001</size>
          </box>
        </geometry>
        <surface>
          <contact>
            <ode/>
          </contact>
          <friction>
            <ode/>
          </friction>
        </surface>
      </collision>
      <collision name='body_fixed_joint_lump__camera_rearDown_collision_4'>
        <pose frame=''>-0.0825 0.0125 -0.04365 3.14159 1.57079 3e-06</pose>
        <geometry>
          <box>
            <size>0.001 0.001 0.001</size>
          </box>
        </geometry>
        <surface>
          <contact>
            <ode/>
          </contact>
          <friction>
            <ode/>
          </friction>
        </surface>
      </collision>
      <collision name='body_fixed_joint_lump__camera_right_collision_5'>
        <pose frame=''>-0.041 -0.082 -0.0176 -3.14159 0.2618 -1.5708</pose>
        <geometry>
          <box>
            <size>0.001 0.001 0.001</size>
          </box>
        </geometry>
        <surface>
          <contact>
            <ode/>
          </contact>
          <friction>
            <ode/>
          </friction>
        </surface>
      </collision>
      <collision name='body_fixed_joint_lump__imu_link_collision_6'>
        <pose frame=''>-0.01592 -0.06659 -0.00617 0 -0 0</pose>
        <geometry>
          <box>
            <size>0.001 0.001 0.001</size>
          </box>
        </geometry>
        <surface>
          <contact>
            <ode/>
          </contact>
          <friction>
            <ode>
              <mu>0.2</mu>
              <mu2>0.2</mu2>
            </ode>
          </friction>
        </surface>
      </collision>
      <collision name='body_fixed_joint_lump__ultraSound_face_collision_7'>
        <pose frame=''>0.2747 0 -0.0088 0 -0 0</pose>
        <geometry>
          <box>
            <size>0.001 0.001 0.001</size>
          </box>
        </geometry>
      </collision>
      <collision name='body_fixed_joint_lump__ultraSound_left_collision_8'>
        <pose frame=''>-0.0535 0.0826 0.00868 0 0.2618 1.5708</pose>
        <geometry>
          <box>
            <size>0.001 0.001 0.001</size>
          </box>
        </geometry>
      </collision>
      <collision name='body_fixed_joint_lump__ultraSound_right_collision_9'>
        <pose frame=''>-0.0535 -0.0826 0.00868 0 0.2618 -1.5708</pose>
        <geometry>
          <box>
            <size>0.001 0.001 0.001</size>
          </box>
        </geometry>
      </collision>
      <visual name='body_visual'>
        <pose frame=''>0 0 0 0 -0 0</pose>
        <geometry>
          <box>
            <size>0.001 0.001 0.001</size>
          </box>
        </geometry>
        <material>
          <script>
            <name>Gazebo/White</name>
            <uri>file://media/materials/scripts/gazebo.material</uri>
          </script>
        </material>
      </visual>
      <visual name='body_visual_visual_1'>
        <pose frame=''>0 0 0 0 -0 0</pose>
        <geometry>
          <mesh>
            <scale>1 1 1</scale>
            <uri>model://go1_description/meshes/trunk.dae</uri>
          </mesh>
        </geometry>
        <material>
          <script>
            <name>Gazebo/White</name>
            <uri>file://media/materials/scripts/gazebo.material</uri>
          </script>
        </material>
      </visual>
      <visual name='body_fixed_joint_lump__camera_chin_visual_2'>
        <pose frame=''>0.2522 0.0125 -0.0436 3.14159 1.57079 3e-06</pose>
        <geometry>
          <mesh>
            <scale>1 1 1</scale>
            <uri>model://go1_description/meshes/depthCamera.dae</uri>
          </mesh>
        </geometry>
        <material>
          <script>
            <uri>__default__</uri>
            <name>__default__</name>
          </script>
        </material>
      </visual>
      <visual name='body_fixed_joint_lump__camera_face_visual_3'>
        <pose frame=''>0.2785 0.0125 0.0167 -3.14159 -0 0</pose>
        <geometry>
          <mesh>
            <scale>1 1 1</scale>
            <uri>model://go1_description/meshes/depthCamera.dae</uri>
          </mesh>
        </geometry>
        <material>
          <script>
            <uri>__default__</uri>
            <name>__default__</name>
          </script>
        </material>
      </visual>
      <visual name='body_fixed_joint_lump__camera_left_visual_4'>
        <pose frame=''>-0.066 0.082 -0.0176 -3.14159 0.2618 1.5708</pose>
        <geometry>
          <mesh>
            <scale>1 1 1</scale>
            <uri>model://go1_description/meshes/depthCamera.dae</uri>
          </mesh>
        </geometry>
        <material>
          <script>
            <uri>__default__</uri>
            <name>__default__</name>
          </script>
        </material>
      </visual>
      <visual name='body_fixed_joint_lump__camera_rearDown_visual_5'>
        <pose frame=''>-0.0825 0.0125 -0.04365 3.14159 1.57079 3e-06</pose>
        <geometry>
          <mesh>
            <scale>1 1 1</scale>
            <uri>model://go1_description/meshes/depthCamera.dae</uri>
          </mesh>
        </geometry>
        <material>
          <script>
            <uri>__default__</uri>
            <name>__default__</name>
          </script>
        </material>
      </visual>
      <visual name='body_fixed_joint_lump__camera_right_visual_6'>
        <pose frame=''>-0.041 -0.082 -0.0176 -3.14159 0.2618 -1.5708</pose>
        <geometry>
          <mesh>
            <scale>1 1 1</scale>
            <uri>model://go1_description/meshes/depthCamera.dae</uri>
          </mesh>
        </geometry>
        <material>
          <script>
            <uri>__default__</uri>
            <name>__default__</name>
          </script>
        </material>
      </visual>
      <visual name='body_fixed_joint_lump__imu_link_visual_7'>
        <pose frame=''>-0.01592 -0.06659 -0.00617 0 -0 0</pose>
        <geometry>
          <box>
            <size>0.001 0.001 0.001</size>
          </box>
        </geometry>
        <material>
          <script>
            <name>Gazebo/Red</name>
            <uri>file://media/materials/scripts/gazebo.material</uri>
          </script>
        </material>
      </visual>
      <visual name='body_fixed_joint_lump__ultraSound_face_visual_8'>
        <pose frame=''>0.2747 0 -0.0088 0 -0 0</pose>
        <geometry>
          <mesh>
            <scale>1 1 1</scale>
            <uri>model://go1_description/meshes/ultraSound.dae</uri>
          </mesh>
        </geometry>
      </visual>
      <visual name='body_fixed_joint_lump__ultraSound_left_visual_9'>
        <pose frame=''>-0.0535 0.0826 0.00868 0 0.2618 1.5708</pose>
        <geometry>
          <mesh>
            <scale>1 1 1</scale>
            <uri>model://go1_description/meshes/ultraSound.dae</uri>
          </mesh>
        </geometry>
      </visual>
      <visual name='body_fixed_joint_lump__ultraSound_right_visual_10'>
        <pose frame=''>-0.0535 -0.0826 0.00868 0 0.2618 -1.5708</pose>
        <geometry>
          <mesh>
            <scale>1 1 1</scale>
            <uri>model://go1_description/meshes/ultraSound.dae</uri>
          </mesh>
        </geometry>
      </visual>
      <velocity_decay/>
      <velocity_decay/>
      <velocity_decay/>
      <sensor name='camera_chin_camera' type='depth'>
        <update_rate>16</update_rate>
        <camera name='__default__'>
          <horizontal_fov>2.094</horizontal_fov>
          <image>
            <width>928</width>
            <height>800</height>
            <format>R8G8B8</format>
          </image>
          <clip>
            <near>0.1</near>
            <far>5</far>
          </clip>
        </camera>
        <plugin name='camera_chin_controller' filename='libgazebo_ros_openni_kinect.so'>
          <baseline>0.025</baseline>
          <alwaysOn>1</alwaysOn>
          <updateRate>0.0</updateRate>
          <cameraName>camera_chin_ir</cameraName>
          <imageTopicName>/camera_chin/color/image_raw</imageTopicName>
          <cameraInfoTopicName>/camera_chin/color/camera_info</cameraInfoTopicName>
          <depthImageTopicName>/camera_chin/depth/image_raw</depthImageTopicName>
          <depthImageInfoTopicName>/camera_chin/depth/camera_info</depthImageInfoTopicName>
          <pointCloudTopicName>/cam2/point_cloud_chin</pointCloudTopicName>
          <frameName>camera_optical_chin</frameName>
          <pointCloudCutoff>0.1</pointCloudCutoff>
          <pointCloudCutoffMax>1.5</pointCloudCutoffMax>
          <distortionK1>0.0</distortionK1>
          <distortionK2>0.0</distortionK2>
          <distortionK3>0.0</distortionK3>
          <distortionT1>0.0</distortionT1>
          <distortionT2>0.0</distortionT2>
          <CxPrime>0</CxPrime>
          <Cx>0.0045</Cx>
          <Cy>0.0039</Cy>
          <focalLength>0</focalLength>
          <hackBaseline>0</hackBaseline>
        </plugin>
        <pose frame=''>0.2522 0.0125 -0.0436 3.14159 1.57079 3e-06</pose>
      </sensor>
      <velocity_decay/>
      <sensor name='camera_face_camera' type='depth'>
        <update_rate>16</update_rate>
        <camera name='__default__'>
          <horizontal_fov>2.094</horizontal_fov>
          <image>
            <width>928</width>
            <height>800</height>
            <format>R8G8B8</format>
          </image>
          <clip>
            <near>0.1</near>
            <far>5</far>
          </clip>
        </camera>
        <plugin name='camera_face_controller' filename='libgazebo_ros_openni_kinect.so'>
          <baseline>0.025</baseline>
          <alwaysOn>1</alwaysOn>
          <updateRate>0.0</updateRate>
          <cameraName>camera_face_ir</cameraName>
          <imageTopicName>/camera_face/color/image_raw</imageTopicName>
          <cameraInfoTopicName>/camera_face/color/camera_info</cameraInfoTopicName>
          <depthImageTopicName>/camera_face/depth/image_raw</depthImageTopicName>
          <depthImageInfoTopicName>/camera_face/depth/camera_info</depthImageInfoTopicName>
          <pointCloudTopicName>/cam1/point_cloud_face</pointCloudTopicName>
          <frameName>camera_optical_face</frameName>
          <pointCloudCutoff>0.1</pointCloudCutoff>
          <pointCloudCutoffMax>1.5</pointCloudCutoffMax>
          <distortionK1>0.0</distortionK1>
          <distortionK2>0.0</distortionK2>
          <distortionK3>0.0</distortionK3>
          <distortionT1>0.0</distortionT1>
          <distortionT2>0.0</distortionT2>
          <CxPrime>0</CxPrime>
          <Cx>0.0045</Cx>
          <Cy>0.0039</Cy>
          <focalLength>0</focalLength>
          <hackBaseline>0</hackBaseline>
        </plugin>
        <pose frame=''>0.2785 0.0125 0.0167 -3.14159 -0 0</pose>
      </sensor>
      <velocity_decay/>
      <sensor name='camera_left_camera' type='depth'>
        <update_rate>16</update_rate>
        <camera name='__default__'>
          <horizontal_fov>2.094</horizontal_fov>
          <image>
            <width>928</width>
            <height>800</height>
            <format>R8G8B8</format>
          </image>
          <clip>
            <near>0.1</near>
            <far>5</far>
          </clip>
        </camera>
        <plugin name='camera_left_controller' filename='libgazebo_ros_openni_kinect.so'>
          <baseline>0.025</baseline>
          <alwaysOn>1</alwaysOn>
          <updateRate>0.0</updateRate>
          <cameraName>camera_left_ir</cameraName>
          <imageTopicName>/camera_left/color/image_raw</imageTopicName>
          <cameraInfoTopicName>/camera_left/color/camera_info</cameraInfoTopicName>
          <depthImageTopicName>/camera_left/depth/image_raw</depthImageTopicName>
          <depthImageInfoTopicName>/camera_left/depth/camera_info</depthImageInfoTopicName>
          <pointCloudTopicName>/cam3/point_cloud_left</pointCloudTopicName>
          <frameName>camera_optical_left</frameName>
          <pointCloudCutoff>0.1</pointCloudCutoff>
          <pointCloudCutoffMax>1.5</pointCloudCutoffMax>
          <distortionK1>0.0</distortionK1>
          <distortionK2>0.0</distortionK2>
          <distortionK3>0.0</distortionK3>
          <distortionT1>0.0</distortionT1>
          <distortionT2>0.0</distortionT2>
          <CxPrime>0</CxPrime>
          <Cx>0.0045</Cx>
          <Cy>0.0039</Cy>
          <focalLength>0</focalLength>
          <hackBaseline>0</hackBaseline>
        </plugin>
        <pose frame=''>-0.066 0.082 -0.0176 -3.14159 0.2618 1.5708</pose>
      </sensor>
      <velocity_decay/>
      <sensor name='camera_rearDown_camera' type='depth'>
        <update_rate>16</update_rate>
        <camera name='__default__'>
          <horizontal_fov>2.094</horizontal_fov>
          <image>
            <width>928</width>
            <height>800</height>
            <format>R8G8B8</format>
          </image>
          <clip>
            <near>0.1</near>
            <far>5</far>
          </clip>
        </camera>
        <plugin name='camera_rearDown_controller' filename='libgazebo_ros_openni_kinect.so'>
          <baseline>0.025</baseline>
          <alwaysOn>1</alwaysOn>
          <updateRate>0.0</updateRate>
          <cameraName>camera_rearDown_ir</cameraName>
          <imageTopicName>/camera_rearDown/color/image_raw</imageTopicName>
          <cameraInfoTopicName>/camera_rearDown/color/camera_info</cameraInfoTopicName>
          <depthImageTopicName>/camera_rearDown/depth/image_raw</depthImageTopicName>
          <depthImageInfoTopicName>/camera_rearDown/depth/camera_info</depthImageInfoTopicName>
          <pointCloudTopicName>/cam5/point_cloud_rearDown</pointCloudTopicName>
          <frameName>camera_optical_rearDown</frameName>
          <pointCloudCutoff>0.1</pointCloudCutoff>
          <pointCloudCutoffMax>1.5</pointCloudCutoffMax>
          <distortionK1>0.0</distortionK1>
          <distortionK2>0.0</distortionK2>
          <distortionK3>0.0</distortionK3>
          <distortionT1>0.0</distortionT1>
          <distortionT2>0.0</distortionT2>
          <CxPrime>0</CxPrime>
          <Cx>0.0045</Cx>
          <Cy>0.0039</Cy>
          <focalLength>0</focalLength>
          <hackBaseline>0</hackBaseline>
        </plugin>
        <pose frame=''>-0.0825 0.0125 -0.04365 3.14159 1.57079 3e-06</pose>
      </sensor>
      <velocity_decay/>
      <sensor name='camera_right_camera' type='depth'>
        <update_rate>16</update_rate>
        <camera name='__default__'>
          <horizontal_fov>2.094</horizontal_fov>
          <image>
            <width>928</width>
            <height>800</height>
            <format>R8G8B8</format>
          </image>
          <clip>
            <near>0.1</near>
            <far>5</far>
          </clip>
        </camera>
        <plugin name='camera_right_controller' filename='libgazebo_ros_openni_kinect.so'>
          <baseline>0.025</baseline>
          <alwaysOn>1</alwaysOn>
          <updateRate>0.0</updateRate>
          <cameraName>camera_right_ir</cameraName>
          <imageTopicName>/camera_right/color/image_raw</imageTopicName>
          <cameraInfoTopicName>/camera_right/color/camera_info</cameraInfoTopicName>
          <depthImageTopicName>/camera_right/depth/image_raw</depthImageTopicName>
          <depthImageInfoTopicName>/camera_right/depth/camera_info</depthImageInfoTopicName>
          <pointCloudTopicName>/cam4/point_cloud_right</pointCloudTopicName>
          <frameName>camera_optical_right</frameName>
          <pointCloudCutoff>0.1</pointCloudCutoff>
          <pointCloudCutoffMax>1.5</pointCloudCutoffMax>
          <distortionK1>0.0</distortionK1>
          <distortionK2>0.0</distortionK2>
          <distortionK3>0.0</distortionK3>
          <distortionT1>0.0</distortionT1>
          <distortionT2>0.0</distortionT2>
          <CxPrime>0</CxPrime>
          <Cx>0.0045</Cx>
          <Cy>0.0039</Cy>
          <focalLength>0</focalLength>
          <hackBaseline>0</hackBaseline>
        </plugin>
        <pose frame=''>-0.041 -0.082 -0.0176 -3.14159 0.2618 -1.5708</pose>
      </sensor>
      <velocity_decay/>
      <gravity>1</gravity>
      <sensor name='imu_sensor' type='imu'>
        <always_on>1</always_on>
        <update_rate>1000</update_rate>
        <visualize>1</visualize>
        <topic>__default_topic__</topic>
        <plugin name='imu_plugin' filename='libgazebo_ros_imu_sensor.so'>
          <topicName>trunk_imu</topicName>
          <bodyName>imu_link</bodyName>
          <updateRateHZ>1000.0</updateRateHZ>
          <gaussianNoise>0.0</gaussianNoise>
          <xyzOffset>0 0 0</xyzOffset>
          <rpyOffset>0 0 0</rpyOffset>
          <frameName>imu_link</frameName>
        </plugin>
        <pose frame=''>-0.01592 -0.06659 -0.00617 0 -0 0</pose>
      </sensor>
      <gravity>1</gravity>
      <velocity_decay/>
    </link>
    <link name='hip2'>
      <pose frame=''>0.1881 -0.04675 0 0 -0 0</pose>
      <inertial>
        <pose frame=''>-0.00541 0.00074 6e-06 0 -0 0</pose>
        <mass>0.591</mass>
        <inertia>
          <ixx>0.000374268</ixx>
          <ixy>-3.68444e-05</ixy>
          <ixz>-9.86754e-07</ixz>
          <iyy>0.000635924</iyy>
          <iyz>1.17289e-06</iyz>
          <izz>0.000457647</izz>
        </inertia>
      </inertial>
      <collision name='hip2_collision_collision'>
        <pose frame=''>0 0 0 1.5708 -0 0</pose>
        <geometry>
          <cylinder>
            <length>0.04</length>
            <radius>0.046</radius>
          </cylinder>
        </geometry>
        <surface>
          <contact>
            <ode/>
          </contact>
          <friction>
            <ode>
              <mu>0.2</mu>
              <mu2>0.2</mu2>
            </ode>
          </friction>
        </surface>
      </collision>
      <visual name='hip2_visual_visual'>
        <pose frame=''>0 0 0 -3.14159 -0 0</pose>
        <geometry>
          <mesh>
            <scale>1 1 1</scale>
            <uri>model://go1_description/meshes/hip.dae</uri>
          </mesh>
        </geometry>
        <material>
          <script>
            <name>Gazebo/DarkGrey</name>
            <uri>file://media/materials/scripts/gazebo.material</uri>
          </script>
        </material>
      </visual>
      <gravity>1</gravity>
      <velocity_decay/>
    </link>
    <joint name='10' type='revolute'>
      <child>hip2</child>
      <parent>body</parent>
      <axis>
        <xyz>1 0 0</xyz>
        <limit>
          <lower>-1.0472</lower>
          <upper>1.0472</upper>
          <effort>23.7</effort>
          <velocity>30.1</velocity>
        </limit>
        <dynamics>
          <damping>0.01</damping>
          <friction>0.2</friction>
          <spring_reference>0</spring_reference>
          <spring_stiffness>0</spring_stiffness>
        </dynamics>
        <use_parent_model_frame>0</use_parent_model_frame>
      </axis>
    </joint>
    <link name='upper2'>
      <pose frame=''>0.1881 -0.12675 0 3.14159 1.57079 3.14159</pose>
      <inertial>
        <pose frame=''>-0.003468 0.018947 -0.032736 0 -0 0</pose>
        <mass>0.92</mass>
        <inertia>
          <ixx>0.00585156</ixx>
          <ixy>-1.78328e-06</ixy>
          <ixz>0.000328291</ixz>
          <iyy>0.00559616</iyy>
          <iyz>-2.14307e-05</iyz>
          <izz>0.00107157</izz>
        </inertia>
      </inertial>
      <collision name='upper2_collision_collision'>
        <pose frame=''>0 0 -0.1065 3.14159 1.57079 3.14159</pose>
        <geometry>
          <box>
            <size>0.213 0.0245 0.034</size>
          </box>
        </geometry>
        <surface>
          <contact>
            <ode>
              <kp>1e+06</kp>
              <kd>1</kd>
            </ode>
          </contact>
          <friction>
            <ode>
              <mu>0.2</mu>
              <mu2>0.2</mu2>
            </ode>
          </friction>
        </surface>
      </collision>
      <visual name='upper2_visual_visual'>
        <pose frame=''>0 0 0 0 -0 0</pose>
        <geometry>
          <mesh>
            <scale>1 1 1</scale>
            <uri>model://go1_description/meshes/thigh_mirror.dae</uri>
          </mesh>
        </geometry>
        <material>
          <script>
            <name>Gazebo/DarkGrey</name>
            <uri>file://media/materials/scripts/gazebo.material</uri>
          </script>
        </material>
      </visual>
      <gravity>1</gravity>
      <velocity_decay/>
      <self_collide>0</self_collide>
    </link>
    <joint name='4' type='revolute'>
      <child>upper2</child>
      <parent>hip2</parent>
      <axis>
        <xyz>0 -1 0</xyz>
        <limit>
          <lower>-6.28319</lower>
          <upper>6.28319</upper>
          <effort>23.7</effort>
          <velocity>30.1</velocity>
        </limit>
        <dynamics>
          <damping>0.01</damping>
          <friction>0.2</friction>
          <spring_reference>0</spring_reference>
          <spring_stiffness>0</spring_stiffness>
        </dynamics>
        <use_parent_model_frame>0</use_parent_model_frame>
      </axis>
    </joint>
    <link name='lower2'>
      <pose frame=''>-0.0249 -0.12675 -0 3.14159 -1.57079 3.14159</pose>
      <inertial>
        <pose frame=''>0.006286 0.001307 -0.122269 0 -0 0</pose>
        <mass>0.131</mass>
        <inertia>
          <ixx>0.00293919</ixx>
          <ixy>1.4409e-06</ixy>
          <ixz>-0.00010536</ixz>
          <iyy>0.00295577</iyy>
          <iyz>-2.43978e-05</iyz>
          <izz>3.02734e-05</izz>
        </inertia>
      </inertial>
      <collision name='lower2_collision_collision'>
        <pose frame=''>0 0 -0.1065 3.14159 1.57079 3.14159</pose>
        <geometry>
          <box>
            <size>0.213 0.016 0.016</size>
          </box>
        </geometry>
        <surface>
          <contact>
            <ode/>
          </contact>
          <friction>
            <ode>
              <mu>0.2</mu>
              <mu2>0.2</mu2>
            </ode>
          </friction>
        </surface>
      </collision>
      <visual name='lower2_visual_visual'>
        <pose frame=''>0 0 0 0 -0 0</pose>
        <geometry>
          <mesh>
            <scale>1 1 1</scale>
            <uri>model://go1_description/meshes/calf.dae</uri>
          </mesh>
        </geometry>
        <material>
          <script>
            <uri>__default__</uri>
            <name>__default__</name>
          </script>
        </material>
      </visual>
      <gravity>1</gravity>
      <velocity_decay/>
      <self_collide>0</self_collide>
    </link>
    <joint name='5' type='revolute'>
      <child>lower2</child>
      <parent>upper2</parent>
      <axis>
        <xyz>0 1 0</xyz>
        <limit>
          <lower>-6.28319</lower>
          <upper>6.28319</upper>
          <effort>23.7</effort>
          <velocity>30.1</velocity>
        </limit>
        <dynamics>
          <damping>0.01</damping>
          <friction>0.2</friction>
          <spring_reference>0</spring_reference>
          <spring_stiffness>0</spring_stiffness>
        </dynamics>
        <use_parent_model_frame>0</use_parent_model_frame>
      </axis>
    </joint>
    <link name='toe2'>
      <pose frame=''>0.1881 -0.12675 0 3.14159 -1.57079 3.14159</pose>
      <inertial>
        <pose frame=''>0 0 0 0 -0 0</pose>
        <mass>0.06</mass>
        <inertia>
          <ixx>9.6e-06</ixx>
          <ixy>0</ixy>
          <ixz>0</ixz>
          <iyy>9.6e-06</iyy>
          <iyz>0</iyz>
          <izz>9.6e-06</izz>
        </inertia>
      </inertial>
      <collision name='toe2_collision_collision'>
        <pose frame=''>0 0 0 0 -0 0</pose>
        <geometry>
          <sphere>
            <radius>0.02</radius>
          </sphere>
        </geometry>
        <surface>
          <contact>
            <ode>
              <kp>1e+06</kp>
              <kd>1</kd>
            </ode>
          </contact>
          <friction>
            <ode>
              <mu>0.6</mu>
              <mu2>0.6</mu2>
            </ode>
          </friction>
        </surface>
      </collision>
      <visual name='toe2_visual_visual'>
        <pose frame=''>0 0 0 0 -0 0</pose>
        <geometry>
          <sphere>
            <radius>0.01</radius>
          </sphere>
        </geometry>
        <material>
          <script>
            <name>Gazebo/DarkGrey</name>
            <uri>file://media/materials/scripts/gazebo.material</uri>
          </script>
        </material>
      </visual>
      <velocity_decay/>
      <sensor name='toe2_contact' type='contact'>
        <plugin name='toe2_plugin' filename='libgazebo_ros_bumper.so'>
          <alwaysOn>1</alwaysOn>
          <updateRate>500</updateRate>
          <bumperTopicName>gazebo/toe2_contact_state</bumperTopicName>
          <frameName>world</frameName>
        </plugin>
        <contact>
          <collision>toe2_collision</collision>
          <topic>__default_topic__</topic>
        </contact>
        <update_rate>500</update_rate>
      </sensor>
      <gravity>1</gravity>
      <velocity_decay/>
      <self_collide>0</self_collide>
    </link>
    <joint name='jtoe2' type='fixed'>
      <child>toe2</child>
      <parent>lower2</parent>
      <axis>
        <dynamics>
          <spring_reference>0</spring_reference>
          <spring_stiffness>0</spring_stiffness>
        </dynamics>
        <xyz>0 0 1</xyz>
        <use_parent_model_frame>0</use_parent_model_frame>
        <limit>
          <lower>-1e+16</lower>
          <upper>1e+16</upper>
        </limit>
      </axis>
      <physics>
        <ode>
          <limit>
            <cfm>0</cfm>
            <erp>0.2</erp>
          </limit>
        </ode>
      </physics>
    </joint>
    <link name='hip3'>
      <pose frame=''>-0.1881 -0.04675 0 0 -0 0</pose>
      <inertial>
        <pose frame=''>0.00541 0.00074 6e-06 0 -0 0</pose>
        <mass>0.591</mass>
        <inertia>
          <ixx>0.000374268</ixx>
          <ixy>3.68444e-05</ixy>
          <ixz>9.86754e-07</ixz>
          <iyy>0.000635924</iyy>
          <iyz>1.17289e-06</iyz>
          <izz>0.000457647</izz>
        </inertia>
      </inertial>
      <collision name='hip3_collision_collision'>
        <pose frame=''>0 0 0 1.5708 -0 0</pose>
        <geometry>
          <cylinder>
            <length>0.04</length>
            <radius>0.046</radius>
          </cylinder>
        </geometry>
        <surface>
          <contact>
            <ode/>
          </contact>
          <friction>
            <ode>
              <mu>0.2</mu>
              <mu2>0.2</mu2>
            </ode>
          </friction>
        </surface>
      </collision>
      <visual name='hip3_visual_visual'>
        <pose frame=''>0 0 0 0 -0 3.14159</pose>
        <geometry>
          <mesh>
            <scale>1 1 1</scale>
            <uri>model://go1_description/meshes/hip.dae</uri>
          </mesh>
        </geometry>
        <material>
          <script>
            <name>Gazebo/DarkGrey</name>
            <uri>file://media/materials/scripts/gazebo.material</uri>
          </script>
        </material>
      </visual>
      <gravity>1</gravity>
      <velocity_decay/>
    </link>
    <joint name='11' type='revolute'>
      <child>hip3</child>
      <parent>body</parent>
      <axis>
        <xyz>1 0 0</xyz>
        <limit>
          <lower>-1.0472</lower>
          <upper>1.0472</upper>
          <effort>23.7</effort>
          <velocity>30.1</velocity>
        </limit>
        <dynamics>
          <damping>0.01</damping>
          <friction>0.2</friction>
          <spring_reference>0</spring_reference>
          <spring_stiffness>0</spring_stiffness>
        </dynamics>
        <use_parent_model_frame>0</use_parent_model_frame>
      </axis>
    </joint>
    <link name='upper3'>
      <pose frame=''>-0.1881 -0.12675 0 3.14159 1.57079 3.14159</pose>
      <inertial>
        <pose frame=''>-0.003468 0.018947 -0.032736 0 -0 0</pose>
        <mass>0.92</mass>
        <inertia>
          <ixx>0.00585156</ixx>
          <ixy>-1.78328e-06</ixy>
          <ixz>0.000328291</ixz>
          <iyy>0.00559616</iyy>
          <iyz>-2.14307e-05</iyz>
          <izz>0.00107157</izz>
        </inertia>
      </inertial>
      <collision name='upper3_collision_collision'>
        <pose frame=''>0 0 -0.1065 3.14159 1.57079 3.14159</pose>
        <geometry>
          <box>
            <size>0.213 0.0245 0.034</size>
          </box>
        </geometry>
        <surface>
          <contact>
            <ode>
              <kp>1e+06</kp>
              <kd>1</kd>
            </ode>
          </contact>
          <friction>
            <ode>
              <mu>0.2</mu>
              <mu2>0.2</mu2>
            </ode>
          </friction>
        </surface>
      </collision>
      <visual name='upper3_visual_visual'>
        <pose frame=''>0 0 0 0 -0 0</pose>
        <geometry>
          <mesh>
            <scale>1 1 1</scale>
            <uri>model://go1_description/meshes/thigh_mirror.dae</uri>
          </mesh>
        </geometry>
        <material>
          <script>
            <name>Gazebo/DarkGrey</name>
            <uri>file://media/materials/scripts/gazebo.material</uri>
          </script>
        </material>
      </visual>
      <gravity>1</gravity>
      <velocity_decay/>
      <self_collide>0</self_collide>
    </link>
    <joint name='6' type='revolute'>
      <child>upper3</child>
      <parent>hip3</parent>
      <axis>
        <xyz>0 -1 0</xyz>
        <limit>
          <lower>-6.28319</lower>
          <upper>6.28319</upper>
          <effort>23.7</effort>
          <velocity>30.1</velocity>
        </limit>
        <dynamics>
          <damping>0.01</damping>
          <friction>0.2</friction>
          <spring_reference>0</spring_reference>
          <spring_stiffness>0</spring_stiffness>
        </dynamics>
        <use_parent_model_frame>0</use_parent_model_frame>
      </axis>
    </joint>
    <link name='lower3'>
      <pose frame=''>-0.4011 -0.12675 -0 3.14159 -1.57079 3.14159</pose>
      <inertial>
        <pose frame=''>0.006286 0.001307 -0.122269 0 -0 0</pose>
        <mass>0.131</mass>
        <inertia>
          <ixx>0.00293919</ixx>
          <ixy>1.4409e-06</ixy>
          <ixz>-0.00010536</ixz>
          <iyy>0.00295577</iyy>
          <iyz>-2.43978e-05</iyz>
          <izz>3.02734e-05</izz>
        </inertia>
      </inertial>
      <collision name='lower3_collision_collision'>
        <pose frame=''>0 0 -0.1065 3.14159 1.57079 3.14159</pose>
        <geometry>
          <box>
            <size>0.213 0.016 0.016</size>
          </box>
        </geometry>
        <surface>
          <contact>
            <ode/>
          </contact>
          <friction>
            <ode>
              <mu>0.2</mu>
              <mu2>0.2</mu2>
            </ode>
          </friction>
        </surface>
      </collision>
      <visual name='lower3_visual_visual'>
        <pose frame=''>0 0 0 0 -0 0</pose>
        <geometry>
          <mesh>
            <scale>1 1 1</scale>
            <uri>model://go1_description/meshes/calf.dae</uri>
          </mesh>
        </geometry>
        <material>
          <script>
            <uri>__default__</uri>
            <name>__default__</name>
          </script>
        </material>
      </visual>
      <gravity>1</gravity>
      <velocity_decay/>
      <self_collide>0</self_collide>
    </link>
    <joint name='7' type='revolute'>
      <child>lower3</child>
      <parent>upper3</parent>
      <axis>
        <xyz>0 1 0</xyz>
        <limit>
          <lower>-6.28319</lower>
          <upper>6.28319</upper>
          <effort>23.7</effort>
          <velocity>30.1</velocity>
        </limit>
        <dynamics>
          <damping>0.01</damping>
          <friction>0.2</friction>
          <spring_reference>0</spring_reference>
          <spring_stiffness>0</spring_stiffness>
        </dynamics>
        <use_parent_model_frame>0</use_parent_model_frame>
      </axis>
    </joint>
    <link name='toe3'>
      <pose frame=''>-0.1881 -0.12675 0 3.14159 -1.57079 3.14159</pose>
      <inertial>
        <pose frame=''>0 0 0 0 -0 0</pose>
        <mass>0.06</mass>
        <inertia>
          <ixx>9.6e-06</ixx>
          <ixy>0</ixy>
          <ixz>0</ixz>
          <iyy>9.6e-06</iyy>
          <iyz>0</iyz>
          <izz>9.6e-06</izz>
        </inertia>
      </inertial>
      <collision name='toe3_collision_collision'>
        <pose frame=''>0 0 0 0 -0 0</pose>
        <geometry>
          <sphere>
            <radius>0.02</radius>
          </sphere>
        </geometry>
        <surface>
          <contact>
            <ode>
              <kp>1e+06</kp>
              <kd>1</kd>
            </ode>
          </contact>
          <friction>
            <ode>
              <mu>0.6</mu>
              <mu2>0.6</mu2>
            </ode>
          </friction>
        </surface>
      </collision>
      <visual name='toe3_visual_visual'>
        <pose frame=''>0 0 0 0 -0 0</pose>
        <geometry>
          <sphere>
            <radius>0.01</radius>
          </sphere>
        </geometry>
        <material>
          <script>
            <name>Gazebo/DarkGrey</name>
            <uri>file://media/materials/scripts/gazebo.material</uri>
          </script>
        </material>
      </visual>
      <velocity_decay/>
      <sensor name='toe3_contact' type='contact'>
        <plugin name='toe3_plugin' filename='libgazebo_ros_bumper.so'>
          <alwaysOn>1</alwaysOn>
          <updateRate>500</updateRate>
          <bumperTopicName>gazebo/toe3_contact_state</bumperTopicName>
          <frameName>world</frameName>
        </plugin>
        <contact>
          <collision>toe3_collision</collision>
          <topic>__default_topic__</topic>
        </contact>
        <update_rate>500</update_rate>
      </sensor>
      <gravity>1</gravity>
      <velocity_decay/>
      <self_collide>0</self_collide>
    </link>
    <joint name='jtoe3' type='fixed'>
      <child>toe3</child>
      <parent>lower3</parent>
      <axis>
        <dynamics>
          <spring_reference>0</spring_reference>
          <spring_stiffness>0</spring_stiffness>
        </dynamics>
        <xyz>0 0 1</xyz>
        <use_parent_model_frame>0</use_parent_model_frame>
        <limit>
          <lower>-1e+16</lower>
          <upper>1e+16</upper>
        </limit>
      </axis>
      <physics>
        <ode>
          <limit>
            <cfm>0</cfm>
            <erp>0.2</erp>
          </limit>
        </ode>
      </physics>
    </joint>
    <link name='hip0'>
      <pose frame=''>0.1881 0.04675 0 0 -0 0</pose>
      <inertial>
        <pose frame=''>-0.00541 -0.00074 6e-06 0 -0 0</pose>
        <mass>0.591</mass>
        <inertia>
          <ixx>0.000374268</ixx>
          <ixy>3.68444e-05</ixy>
          <ixz>-9.86754e-07</ixz>
          <iyy>0.000635924</iyy>
          <iyz>-1.17289e-06</iyz>
          <izz>0.000457647</izz>
        </inertia>
      </inertial>
      <collision name='hip0_collision_collision'>
        <pose frame=''>0 0 0 1.5708 -0 0</pose>
        <geometry>
          <cylinder>
            <length>0.04</length>
            <radius>0.046</radius>
          </cylinder>
        </geometry>
        <surface>
          <contact>
            <ode/>
          </contact>
          <friction>
            <ode>
              <mu>0.2</mu>
              <mu2>0.2</mu2>
            </ode>
          </friction>
        </surface>
      </collision>
      <visual name='hip0_visual_visual'>
        <pose frame=''>0 0 0 0 -0 0</pose>
        <geometry>
          <mesh>
            <scale>1 1 1</scale>
            <uri>model://go1_description/meshes/hip.dae</uri>
          </mesh>
        </geometry>
        <material>
          <script>
            <name>Gazebo/DarkGrey</name>
            <uri>file://media/materials/scripts/gazebo.material</uri>
          </script>
        </material>
      </visual>
      <gravity>1</gravity>
      <velocity_decay/>
    </link>
    <joint name='8' type='revolute'>
      <child>hip0</child>
      <parent>body</parent>
      <axis>
        <xyz>1 0 0</xyz>
        <limit>
          <lower>-1.0472</lower>
          <upper>1.0472</upper>
          <effort>23.7</effort>
          <velocity>30.1</velocity>
        </limit>
        <dynamics>
          <damping>0.01</damping>
          <friction>0.2</friction>
          <spring_reference>0</spring_reference>
          <spring_stiffness>0</spring_stiffness>
        </dynamics>
        <use_parent_model_frame>0</use_parent_model_frame>
      </axis>
    </joint>
    <link name='upper0'>
      <pose frame=''>0.1881 0.12675 0 3.14159 1.57079 3.14159</pose>
      <inertial>
        <pose frame=''>-0.003468 -0.018947 -0.032736 0 -0 0</pose>
        <mass>0.92</mass>
        <inertia>
          <ixx>0.00585156</ixx>
          <ixy>1.78328e-06</ixy>
          <ixz>0.000328291</ixz>
          <iyy>0.00559616</iyy>
          <iyz>2.14307e-05</iyz>
          <izz>0.00107157</izz>
        </inertia>
      </inertial>
      <collision name='upper0_collision_collision'>
        <pose frame=''>0 0 -0.1065 3.14159 1.57079 3.14159</pose>
        <geometry>
          <box>
            <size>0.213 0.0245 0.034</size>
          </box>
        </geometry>
        <surface>
          <contact>
            <ode>
              <kp>1e+06</kp>
              <kd>1</kd>
            </ode>
          </contact>
          <friction>
            <ode>
              <mu>0.2</mu>
              <mu2>0.2</mu2>
            </ode>
          </friction>
        </surface>
      </collision>
      <visual name='upper0_visual_visual'>
        <pose frame=''>0 0 0 0 -0 0</pose>
        <geometry>
          <mesh>
            <scale>1 1 1</scale>
            <uri>model://go1_description/meshes/thigh.dae</uri>
          </mesh>
        </geometry>
        <material>
          <script>
            <name>Gazebo/DarkGrey</name>
            <uri>file://media/materials/scripts/gazebo.material</uri>
          </script>
        </material>
      </visual>
      <gravity>1</gravity>
      <velocity_decay/>
      <self_collide>0</self_collide>
    </link>
    <joint name='0' type='revolute'>
      <child>upper0</child>
      <parent>hip0</parent>
      <axis>
        <xyz>0 -1 0</xyz>
        <limit>
          <lower>-6.28319</lower>
          <upper>6.28319</upper>
          <effort>23.7</effort>
          <velocity>30.1</velocity>
        </limit>
        <dynamics>
          <damping>0.01</damping>
          <friction>0.2</friction>
          <spring_reference>0</spring_reference>
          <spring_stiffness>0</spring_stiffness>
        </dynamics>
        <use_parent_model_frame>0</use_parent_model_frame>
      </axis>
    </joint>
    <link name='lower0'>
      <pose frame=''>-0.0249 0.12675 -0 3.14159 -1.57079 3.14159</pose>
      <inertial>
        <pose frame=''>0.006286 0.001307 -0.122269 0 -0 0</pose>
        <mass>0.131</mass>
        <inertia>
          <ixx>0.00293919</ixx>
          <ixy>1.4409e-06</ixy>
          <ixz>-0.00010536</ixz>
          <iyy>0.00295577</iyy>
          <iyz>-2.43978e-05</iyz>
          <izz>3.02734e-05</izz>
        </inertia>
      </inertial>
      <collision name='lower0_collision_collision'>
        <pose frame=''>0 0 -0.1065 3.14159 1.57079 3.14159</pose>
        <geometry>
          <box>
            <size>0.213 0.016 0.016</size>
          </box>
        </geometry>
        <surface>
          <contact>
            <ode/>
          </contact>
          <friction>
            <ode>
              <mu>0.2</mu>
              <mu2>0.2</mu2>
            </ode>
          </friction>
        </surface>
      </collision>
      <visual name='lower0_visual_visual'>
        <pose frame=''>0 0 0 0 -0 0</pose>
        <geometry>
          <mesh>
            <scale>1 1 1</scale>
            <uri>model://go1_description/meshes/calf.dae</uri>
          </mesh>
        </geometry>
        <material>
          <script>
            <uri>__default__</uri>
            <name>__default__</name>
          </script>
        </material>
      </visual>
      <gravity>1</gravity>
      <velocity_decay/>
      <self_collide>0</self_collide>
    </link>
    <joint name='1' type='revolute'>
      <child>lower0</child>
      <parent>upper0</parent>
      <axis>
        <xyz>0 1 0</xyz>
        <limit>
          <lower>-6.28319</lower>
          <upper>6.28319</upper>
          <effort>23.7</effort>
          <velocity>30.1</velocity>
        </limit>
        <dynamics>
          <damping>0.01</damping>
          <friction>0.2</friction>
          <spring_reference>0</spring_reference>
          <spring_stiffness>0</spring_stiffness>
        </dynamics>
        <use_parent_model_frame>0</use_parent_model_frame>
      </axis>
    </joint>
    <link name='toe0'>
      <pose frame=''>0.1881 0.12675 0 3.14159 -1.57079 3.14159</pose>
      <inertial>
        <pose frame=''>0 0 0 0 -0 0</pose>
        <mass>0.06</mass>
        <inertia>
          <ixx>9.6e-06</ixx>
          <ixy>0</ixy>
          <ixz>0</ixz>
          <iyy>9.6e-06</iyy>
          <iyz>0</iyz>
          <izz>9.6e-06</izz>
        </inertia>
      </inertial>
      <collision name='toe0_collision_collision'>
        <pose frame=''>0 0 0 0 -0 0</pose>
        <geometry>
          <sphere>
            <radius>0.02</radius>
          </sphere>
        </geometry>
        <surface>
          <contact>
            <ode>
              <kp>1e+06</kp>
              <kd>1</kd>
            </ode>
          </contact>
          <friction>
            <ode>
              <mu>0.6</mu>
              <mu2>0.6</mu2>
            </ode>
          </friction>
        </surface>
      </collision>
      <visual name='toe0_visual_visual'>
        <pose frame=''>0 0 0 0 -0 0</pose>
        <geometry>
          <sphere>
            <radius>0.01</radius>
          </sphere>
        </geometry>
        <material>
          <script>
            <name>Gazebo/DarkGrey</name>
            <uri>file://media/materials/scripts/gazebo.material</uri>
          </script>
        </material>
      </visual>
      <velocity_decay/>
      <sensor name='toe0_contact' type='contact'>
        <plugin name='toe0_plugin' filename='libgazebo_ros_bumper.so'>
          <alwaysOn>1</alwaysOn>
          <updateRate>500</updateRate>
          <bumperTopicName>gazebo/toe0_contact_state</bumperTopicName>
          <frameName>world</frameName>
        </plugin>
        <contact>
          <collision>toe0_collision</collision>
          <topic>__default_topic__</topic>
        </contact>
        <update_rate>500</update_rate>
      </sensor>
      <gravity>1</gravity>
      <velocity_decay/>
      <self_collide>0</self_collide>
    </link>
    <joint name='jtoe0' type='fixed'>
      <child>toe0</child>
      <parent>lower0</parent>
      <axis>
        <dynamics>
          <spring_reference>0</spring_reference>
          <spring_stiffness>0</spring_stiffness>
        </dynamics>
        <xyz>0 0 1</xyz>
        <use_parent_model_frame>0</use_parent_model_frame>
        <limit>
          <lower>-1e+16</lower>
          <upper>1e+16</upper>
        </limit>
      </axis>
      <physics>
        <ode>
          <limit>
            <cfm>0</cfm>
            <erp>0.2</erp>
          </limit>
        </ode>
      </physics>
    </joint>
    <link name='hip1'>
      <pose frame=''>-0.1881 0.04675 0 0 -0 0</pose>
      <inertial>
        <pose frame=''>0.00541 -0.00074 6e-06 0 -0 0</pose>
        <mass>0.591</mass>
        <inertia>
          <ixx>0.000374268</ixx>
          <ixy>-3.68444e-05</ixy>
          <ixz>9.86754e-07</ixz>
          <iyy>0.000635924</iyy>
          <iyz>-1.17289e-06</iyz>
          <izz>0.000457647</izz>
        </inertia>
      </inertial>
      <collision name='hip1_collision_collision'>
        <pose frame=''>0 0 0 1.5708 -0 0</pose>
        <geometry>
          <cylinder>
            <length>0.04</length>
            <radius>0.046</radius>
          </cylinder>
        </geometry>
        <surface>
          <contact>
            <ode/>
          </contact>
          <friction>
            <ode>
              <mu>0.2</mu>
              <mu2>0.2</mu2>
            </ode>
          </friction>
        </surface>
      </collision>
      <visual name='hip1_visual_visual'>
        <pose frame=''>0 0 0 3.14159 -0 3.14159</pose>
        <geometry>
          <mesh>
            <scale>1 1 1</scale>
            <uri>model://go1_description/meshes/hip.dae</uri>
          </mesh>
        </geometry>
        <material>
          <script>
            <name>Gazebo/DarkGrey</name>
            <uri>file://media/materials/scripts/gazebo.material</uri>
          </script>
        </material>
      </visual>
      <gravity>1</gravity>
      <velocity_decay/>
    </link>
    <joint name='9' type='revolute'>
      <child>hip1</child>
      <parent>body</parent>
      <axis>
        <xyz>1 0 0</xyz>
        <limit>
          <lower>-1.0472</lower>
          <upper>1.0472</upper>
          <effort>23.7</effort>
          <velocity>30.1</velocity>
        </limit>
        <dynamics>
          <damping>0.01</damping>
          <friction>0.2</friction>
          <spring_reference>0</spring_reference>
          <spring_stiffness>0</spring_stiffness>
        </dynamics>
        <use_parent_model_frame>0</use_parent_model_frame>
      </axis>
    </joint>
    <link name='upper1'>
      <pose frame=''>-0.1881 0.12675 0 3.14159 1.57079 3.14159</pose>
      <inertial>
        <pose frame=''>-0.003468 -0.018947 -0.032736 0 -0 0</pose>
        <mass>0.92</mass>
        <inertia>
          <ixx>0.00585156</ixx>
          <ixy>1.78328e-06</ixy>
          <ixz>0.000328291</ixz>
          <iyy>0.00559616</iyy>
          <iyz>2.14307e-05</iyz>
          <izz>0.00107157</izz>
        </inertia>
      </inertial>
      <collision name='upper1_collision_collision'>
        <pose frame=''>0 0 -0.1065 3.14159 1.57079 3.14159</pose>
        <geometry>
          <box>
            <size>0.213 0.0245 0.034</size>
          </box>
        </geometry>
        <surface>
          <contact>
            <ode>
              <kp>1e+06</kp>
              <kd>1</kd>
            </ode>
          </contact>
          <friction>
            <ode>
              <mu>0.2</mu>
              <mu2>0.2</mu2>
            </ode>
          </friction>
        </surface>
      </collision>
      <visual name='upper1_visual_visual'>
        <pose frame=''>0 0 0 0 -0 0</pose>
        <geometry>
          <mesh>
            <scale>1 1 1</scale>
            <uri>model://go1_description/meshes/thigh.dae</uri>
          </mesh>
        </geometry>
        <material>
          <script>
            <name>Gazebo/DarkGrey</name>
            <uri>file://media/materials/scripts/gazebo.material</uri>
          </script>
        </material>
      </visual>
      <gravity>1</gravity>
      <velocity_decay/>
      <self_collide>0</self_collide>
    </link>
    <joint name='2' type='revolute'>
      <child>upper1</child>
      <parent>hip1</parent>
      <axis>
        <xyz>0 -1 0</xyz>
        <limit>
          <lower>-6.28319</lower>
          <upper>6.28319</upper>
          <effort>23.7</effort>
          <velocity>30.1</velocity>
        </limit>
        <dynamics>
          <damping>0.01</damping>
          <friction>0.2</friction>
          <spring_reference>0</spring_reference>
          <spring_stiffness>0</spring_stiffness>
        </dynamics>
        <use_parent_model_frame>0</use_parent_model_frame>
      </axis>
    </joint>
    <link name='lower1'>
      <pose frame=''>-0.4011 0.12675 -0 3.14159 -1.57079 3.14159</pose>
      <inertial>
        <pose frame=''>0.006286 0.001307 -0.122269 0 -0 0</pose>
        <mass>0.131</mass>
        <inertia>
          <ixx>0.00293919</ixx>
          <ixy>1.4409e-06</ixy>
          <ixz>-0.00010536</ixz>
          <iyy>0.00295577</iyy>
          <iyz>-2.43978e-05</iyz>
          <izz>3.02734e-05</izz>
        </inertia>
      </inertial>
      <collision name='lower1_collision_collision'>
        <pose frame=''>0 0 -0.1065 3.14159 1.57079 3.14159</pose>
        <geometry>
          <box>
            <size>0.213 0.016 0.016</size>
          </box>
        </geometry>
        <surface>
          <contact>
            <ode/>
          </contact>
          <friction>
            <ode>
              <mu>0.2</mu>
              <mu2>0.2</mu2>
            </ode>
          </friction>
        </surface>
      </collision>
      <visual name='lower1_visual_visual'>
        <pose frame=''>0 0 0 0 -0 0</pose>
        <geometry>
          <mesh>
            <scale>1 1 1</scale>
            <uri>model://go1_description/meshes/calf.dae</uri>
          </mesh>
        </geometry>
        <material>
          <script>
            <uri>__default__</uri>
            <name>__default__</name>
          </script>
        </material>
      </visual>
      <gravity>1</gravity>
      <velocity_decay/>
      <self_collide>0</self_collide>
    </link>
    <joint name='3' type='revolute'>
      <child>lower1</child>
      <parent>upper1</parent>
      <axis>
        <xyz>0 1 0</xyz>
        <limit>
          <lower>-6.28319</lower>
          <upper>6.28319</upper>
          <effort>23.7</effort>
          <velocity>30.1</velocity>
        </limit>
        <dynamics>
          <damping>0.01</damping>
          <friction>0.2</friction>
          <spring_reference>0</spring_reference>
          <spring_stiffness>0</spring_stiffness>
        </dynamics>
        <use_parent_model_frame>0</use_parent_model_frame>
      </axis>
    </joint>
    <link name='toe1'>
      <pose frame=''>-0.1881 0.12675 0 3.14159 -1.57079 3.14159</pose>
      <inertial>
        <pose frame=''>0 0 0 0 -0 0</pose>
        <mass>0.06</mass>
        <inertia>
          <ixx>9.6e-06</ixx>
          <ixy>0</ixy>
          <ixz>0</ixz>
          <iyy>9.6e-06</iyy>
          <iyz>0</iyz>
          <izz>9.6e-06</izz>
        </inertia>
      </inertial>
      <collision name='toe1_collision_collision'>
        <pose frame=''>0 0 0 0 -0 0</pose>
        <geometry>
          <sphere>
            <radius>0.02</radius>
          </sphere>
        </geometry>
        <surface>
          <contact>
            <ode>
              <kp>1e+06</kp>
              <kd>1</kd>
            </ode>
          </contact>
          <friction>
            <ode>
              <mu>0.6</mu>
              <mu2>0.6</mu2>
            </ode>
          </friction>
        </surface>
      </collision>
      <visual name='toe1_visual_visual'>
        <pose frame=''>0 0 0 0 -0 0</pose>
        <geometry>
          <sphere>
            <radius>0.01</radius>
          </sphere>
        </geometry>
        <material>
          <script>
            <name>Gazebo/DarkGrey</name>
            <uri>file://media/materials/scripts/gazebo.material</uri>
          </script>
        </material>
      </visual>
      <velocity_decay/>
      <sensor name='toe1_contact' type='contact'>
        <plugin name='toe1_plugin' filename='libgazebo_ros_bumper.so'>
          <alwaysOn>1</alwaysOn>
          <updateRate>500</updateRate>
          <bumperTopicName>gazebo/toe1_contact_state</bumperTopicName>
          <frameName>world</frameName>
        </plugin>
        <contact>
          <collision>toe1_collision</collision>
          <topic>__default_topic__</topic>
        </contact>
        <update_rate>500</update_rate>
      </sensor>
      <gravity>1</gravity>
      <velocity_decay/>
      <self_collide>0</self_collide>
    </link>
    <joint name='jtoe1' type='fixed'>
      <child>toe1</child>
      <parent>lower1</parent>
      <axis>
        <dynamics>
          <spring_reference>0</spring_reference>
          <spring_stiffness>0</spring_stiffness>
        </dynamics>
        <xyz>0 0 1</xyz>
        <use_parent_model_frame>0</use_parent_model_frame>
        <limit>
          <lower>-1e+16</lower>
          <upper>1e+16</upper>
        </limit>
      </axis>
      <physics>
        <ode>
          <limit>
            <cfm>0</cfm>
            <erp>0.2</erp>
          </limit>
        </ode>
      </physics>
    </joint>
    <plugin name='gazebo_ros_control' filename='libgazebo_ros_control.so'>
      <robotSimType>gazebo_ros_control/DefaultRobotHWSim</robotSimType>
    </plugin>
    <plugin name='ground_truth_estimator' filename='libground_truth_estimator.so'>
      <updateRateHZ>500.0</updateRateHZ>
    </plugin>
    <static>0</static>
    <plugin name='gazebo_ros_force' filename='libgazebo_ros_force.so'>
      <topicName>/apply_force/trunk</topicName>
      <bodyName>body</bodyName>
      <xyzOffset>0 0 0</xyzOffset>
      <rpyOffset>0 -0 0</rpyOffset>
    </plugin>
  </model>
</sdf>
